[2023-10-24 18:39:22,012:INFO:main:welcone]
[2023-10-24 18:39:29,712:INFO:main:welcone]
[2023-10-24 21:01:24,476:INFO:main:>>>>>> stage Data Ingestion stage started <<<<<<]
[2023-10-24 21:01:24,476:INFO:common:yaml file: config\config.yaml loaded successfully]
[2023-10-24 21:01:24,476:INFO:common:yaml file: params.yaml loaded successfully]
[2023-10-24 21:01:24,476:INFO:common:yaml file: schema.yaml loaded successfully]
[2023-10-24 21:01:24,476:INFO:common:created directory at: artifacts]
[2023-10-24 21:01:24,476:INFO:common:created directory at: artifacts/data_ingestion]
[2023-10-24 21:02:07,382:ERROR:main:<urlopen error [WinError 10060] A connection attempt failed because the connected party did not properly respond after a period of time, or established connection failed because connected host has failed to respond>]
Traceback (most recent call last):
  File "E:\Softwares\Anaconda\envs\ML\lib\urllib\request.py", line 1346, in do_open
    h.request(req.get_method(), req.selector, req.data, headers,
  File "E:\Softwares\Anaconda\envs\ML\lib\http\client.py", line 1285, in request
    self._send_request(method, url, body, headers, encode_chunked)
  File "E:\Softwares\Anaconda\envs\ML\lib\http\client.py", line 1331, in _send_request
    self.endheaders(body, encode_chunked=encode_chunked)
  File "E:\Softwares\Anaconda\envs\ML\lib\http\client.py", line 1280, in endheaders
    self._send_output(message_body, encode_chunked=encode_chunked)
  File "E:\Softwares\Anaconda\envs\ML\lib\http\client.py", line 1040, in _send_output
    self.send(msg)
  File "E:\Softwares\Anaconda\envs\ML\lib\http\client.py", line 980, in send
    self.connect()
  File "E:\Softwares\Anaconda\envs\ML\lib\http\client.py", line 1447, in connect
    super().connect()
  File "E:\Softwares\Anaconda\envs\ML\lib\http\client.py", line 946, in connect
    self.sock = self._create_connection(
  File "E:\Softwares\Anaconda\envs\ML\lib\socket.py", line 844, in create_connection
    raise err
  File "E:\Softwares\Anaconda\envs\ML\lib\socket.py", line 832, in create_connection
    sock.connect(sa)
TimeoutError: [WinError 10060] A connection attempt failed because the connected party did not properly respond after a period of time, or established connection failed because connected host has failed to respond

During handling of the above exception, another exception occurred:

Traceback (most recent call last):
  File "E:\Projects\MLOPS_MLFLOW-\main.py", line 11, in <module>
    data_ingestion.main()
  File "E:\Projects\MLOPS_MLFLOW-\src\MLProject\pipeline\stage_01_data_ingestion.py", line 17, in main
    data_ingestion.download_file()
  File "e:\projects\mlops_mlflow-\src\MLProject\components\data_ingestion.py", line 18, in download_file
    filename, headers = request.urlretrieve(
  File "E:\Softwares\Anaconda\envs\ML\lib\urllib\request.py", line 239, in urlretrieve
    with contextlib.closing(urlopen(url, data)) as fp:
  File "E:\Softwares\Anaconda\envs\ML\lib\urllib\request.py", line 214, in urlopen
    return opener.open(url, data, timeout)
  File "E:\Softwares\Anaconda\envs\ML\lib\urllib\request.py", line 523, in open
    response = meth(req, response)
  File "E:\Softwares\Anaconda\envs\ML\lib\urllib\request.py", line 632, in http_response
    response = self.parent.error(
  File "E:\Softwares\Anaconda\envs\ML\lib\urllib\request.py", line 555, in error
    result = self._call_chain(*args)
  File "E:\Softwares\Anaconda\envs\ML\lib\urllib\request.py", line 494, in _call_chain
    result = func(*args)
  File "E:\Softwares\Anaconda\envs\ML\lib\urllib\request.py", line 747, in http_error_302
    return self.parent.open(new, timeout=req.timeout)
  File "E:\Softwares\Anaconda\envs\ML\lib\urllib\request.py", line 517, in open
    response = self._open(req, data)
  File "E:\Softwares\Anaconda\envs\ML\lib\urllib\request.py", line 534, in _open
    result = self._call_chain(self.handle_open, protocol, protocol +
  File "E:\Softwares\Anaconda\envs\ML\lib\urllib\request.py", line 494, in _call_chain
    result = func(*args)
  File "E:\Softwares\Anaconda\envs\ML\lib\urllib\request.py", line 1389, in https_open
    return self.do_open(http.client.HTTPSConnection, req,
  File "E:\Softwares\Anaconda\envs\ML\lib\urllib\request.py", line 1349, in do_open
    raise URLError(err)
urllib.error.URLError: <urlopen error [WinError 10060] A connection attempt failed because the connected party did not properly respond after a period of time, or established connection failed because connected host has failed to respond>
[2023-10-24 21:07:54,736:INFO:main:>>>>>> stage Data Ingestion stage started <<<<<<]
[2023-10-24 21:07:54,736:INFO:common:yaml file: config\config.yaml loaded successfully]
[2023-10-24 21:07:54,736:INFO:common:yaml file: params.yaml loaded successfully]
[2023-10-24 21:07:54,736:INFO:common:yaml file: schema.yaml loaded successfully]
[2023-10-24 21:07:54,736:INFO:common:created directory at: artifacts]
[2023-10-24 21:07:54,736:INFO:common:created directory at: artifacts/data_ingestion]
[2023-10-24 21:08:37,604:ERROR:main:<urlopen error [WinError 10060] A connection attempt failed because the connected party did not properly respond after a period of time, or established connection failed because connected host has failed to respond>]
Traceback (most recent call last):
  File "E:\Softwares\Anaconda\envs\ML\lib\urllib\request.py", line 1346, in do_open
    h.request(req.get_method(), req.selector, req.data, headers,
  File "E:\Softwares\Anaconda\envs\ML\lib\http\client.py", line 1285, in request
    self._send_request(method, url, body, headers, encode_chunked)
  File "E:\Softwares\Anaconda\envs\ML\lib\http\client.py", line 1331, in _send_request
    self.endheaders(body, encode_chunked=encode_chunked)
  File "E:\Softwares\Anaconda\envs\ML\lib\http\client.py", line 1280, in endheaders
    self._send_output(message_body, encode_chunked=encode_chunked)
  File "E:\Softwares\Anaconda\envs\ML\lib\http\client.py", line 1040, in _send_output
    self.send(msg)
  File "E:\Softwares\Anaconda\envs\ML\lib\http\client.py", line 980, in send
    self.connect()
  File "E:\Softwares\Anaconda\envs\ML\lib\http\client.py", line 1447, in connect
    super().connect()
  File "E:\Softwares\Anaconda\envs\ML\lib\http\client.py", line 946, in connect
    self.sock = self._create_connection(
  File "E:\Softwares\Anaconda\envs\ML\lib\socket.py", line 844, in create_connection
    raise err
  File "E:\Softwares\Anaconda\envs\ML\lib\socket.py", line 832, in create_connection
    sock.connect(sa)
TimeoutError: [WinError 10060] A connection attempt failed because the connected party did not properly respond after a period of time, or established connection failed because connected host has failed to respond

During handling of the above exception, another exception occurred:

Traceback (most recent call last):
  File "E:\Projects\MLOPS_MLFLOW-\main.py", line 11, in <module>
    data_ingestion.main()
  File "E:\Projects\MLOPS_MLFLOW-\src\MLProject\pipeline\stage_01_data_ingestion.py", line 17, in main
    data_ingestion.download_file()
  File "e:\projects\mlops_mlflow-\src\MLProject\components\data_ingestion.py", line 18, in download_file
    filename, headers = request.urlretrieve(
  File "E:\Softwares\Anaconda\envs\ML\lib\urllib\request.py", line 239, in urlretrieve
    with contextlib.closing(urlopen(url, data)) as fp:
  File "E:\Softwares\Anaconda\envs\ML\lib\urllib\request.py", line 214, in urlopen
    return opener.open(url, data, timeout)
  File "E:\Softwares\Anaconda\envs\ML\lib\urllib\request.py", line 523, in open
    response = meth(req, response)
  File "E:\Softwares\Anaconda\envs\ML\lib\urllib\request.py", line 632, in http_response
    response = self.parent.error(
  File "E:\Softwares\Anaconda\envs\ML\lib\urllib\request.py", line 555, in error
    result = self._call_chain(*args)
  File "E:\Softwares\Anaconda\envs\ML\lib\urllib\request.py", line 494, in _call_chain
    result = func(*args)
  File "E:\Softwares\Anaconda\envs\ML\lib\urllib\request.py", line 747, in http_error_302
    return self.parent.open(new, timeout=req.timeout)
  File "E:\Softwares\Anaconda\envs\ML\lib\urllib\request.py", line 517, in open
    response = self._open(req, data)
  File "E:\Softwares\Anaconda\envs\ML\lib\urllib\request.py", line 534, in _open
    result = self._call_chain(self.handle_open, protocol, protocol +
  File "E:\Softwares\Anaconda\envs\ML\lib\urllib\request.py", line 494, in _call_chain
    result = func(*args)
  File "E:\Softwares\Anaconda\envs\ML\lib\urllib\request.py", line 1389, in https_open
    return self.do_open(http.client.HTTPSConnection, req,
  File "E:\Softwares\Anaconda\envs\ML\lib\urllib\request.py", line 1349, in do_open
    raise URLError(err)
urllib.error.URLError: <urlopen error [WinError 10060] A connection attempt failed because the connected party did not properly respond after a period of time, or established connection failed because connected host has failed to respond>
[2023-10-24 21:18:21,252:INFO:main:>>>>>> stage Data Ingestion stage started <<<<<<]
[2023-10-24 21:18:21,252:INFO:common:yaml file: config\config.yaml loaded successfully]
[2023-10-24 21:18:21,252:INFO:common:yaml file: params.yaml loaded successfully]
[2023-10-24 21:18:21,252:INFO:common:yaml file: schema.yaml loaded successfully]
[2023-10-24 21:18:21,252:INFO:common:created directory at: artifacts]
[2023-10-24 21:18:21,252:INFO:common:created directory at: artifacts/data_ingestion]
[2023-10-24 21:18:21,252:ERROR:main:<urlopen error unknown url type: e>]
Traceback (most recent call last):
  File "E:\Projects\MLOPS_MLFLOW-\main.py", line 11, in <module>
    data_ingestion.main()
  File "E:\Projects\MLOPS_MLFLOW-\src\MLProject\pipeline\stage_01_data_ingestion.py", line 17, in main
    data_ingestion.download_file()
  File "e:\projects\mlops_mlflow-\src\MLProject\components\data_ingestion.py", line 18, in download_file
    filename, headers = request.urlretrieve(
  File "E:\Softwares\Anaconda\envs\ML\lib\urllib\request.py", line 239, in urlretrieve
    with contextlib.closing(urlopen(url, data)) as fp:
  File "E:\Softwares\Anaconda\envs\ML\lib\urllib\request.py", line 214, in urlopen
    return opener.open(url, data, timeout)
  File "E:\Softwares\Anaconda\envs\ML\lib\urllib\request.py", line 517, in open
    response = self._open(req, data)
  File "E:\Softwares\Anaconda\envs\ML\lib\urllib\request.py", line 539, in _open
    return self._call_chain(self.handle_open, 'unknown',
  File "E:\Softwares\Anaconda\envs\ML\lib\urllib\request.py", line 494, in _call_chain
    result = func(*args)
  File "E:\Softwares\Anaconda\envs\ML\lib\urllib\request.py", line 1417, in unknown_open
    raise URLError('unknown url type: %s' % type)
urllib.error.URLError: <urlopen error unknown url type: e>
[2023-10-24 21:41:48,695:INFO:main:>>>>>> stage Data Ingestion stage started <<<<<<]
[2023-10-24 21:41:48,711:INFO:common:yaml file: config\config.yaml loaded successfully]
[2023-10-24 21:41:48,711:INFO:common:yaml file: params.yaml loaded successfully]
[2023-10-24 21:41:48,711:INFO:common:yaml file: schema.yaml loaded successfully]
[2023-10-24 21:41:48,711:INFO:common:created directory at: artifacts]
[2023-10-24 21:41:48,711:INFO:common:created directory at: artifacts/data_ingestion]
[2023-10-24 21:42:31,596:ERROR:main:<urlopen error [WinError 10060] A connection attempt failed because the connected party did not properly respond after a period of time, or established connection failed because connected host has failed to respond>]
Traceback (most recent call last):
  File "E:\Softwares\Anaconda\envs\ML\lib\urllib\request.py", line 1346, in do_open
    h.request(req.get_method(), req.selector, req.data, headers,
  File "E:\Softwares\Anaconda\envs\ML\lib\http\client.py", line 1285, in request
    self._send_request(method, url, body, headers, encode_chunked)
  File "E:\Softwares\Anaconda\envs\ML\lib\http\client.py", line 1331, in _send_request
    self.endheaders(body, encode_chunked=encode_chunked)
  File "E:\Softwares\Anaconda\envs\ML\lib\http\client.py", line 1280, in endheaders
    self._send_output(message_body, encode_chunked=encode_chunked)
  File "E:\Softwares\Anaconda\envs\ML\lib\http\client.py", line 1040, in _send_output
    self.send(msg)
  File "E:\Softwares\Anaconda\envs\ML\lib\http\client.py", line 980, in send
    self.connect()
  File "E:\Softwares\Anaconda\envs\ML\lib\http\client.py", line 1447, in connect
    super().connect()
  File "E:\Softwares\Anaconda\envs\ML\lib\http\client.py", line 946, in connect
    self.sock = self._create_connection(
  File "E:\Softwares\Anaconda\envs\ML\lib\socket.py", line 844, in create_connection
    raise err
  File "E:\Softwares\Anaconda\envs\ML\lib\socket.py", line 832, in create_connection
    sock.connect(sa)
TimeoutError: [WinError 10060] A connection attempt failed because the connected party did not properly respond after a period of time, or established connection failed because connected host has failed to respond

During handling of the above exception, another exception occurred:

Traceback (most recent call last):
  File "E:\Projects\MLOPS_MLFLOW-\main.py", line 11, in <module>
    data_ingestion.main()
  File "E:\Projects\MLOPS_MLFLOW-\src\MLProject\pipeline\stage_01_data_ingestion.py", line 17, in main
    data_ingestion.download_file()
  File "e:\projects\mlops_mlflow-\src\MLProject\components\data_ingestion.py", line 18, in download_file
    filename, headers = request.urlretrieve(
  File "E:\Softwares\Anaconda\envs\ML\lib\urllib\request.py", line 239, in urlretrieve
    with contextlib.closing(urlopen(url, data)) as fp:
  File "E:\Softwares\Anaconda\envs\ML\lib\urllib\request.py", line 214, in urlopen
    return opener.open(url, data, timeout)
  File "E:\Softwares\Anaconda\envs\ML\lib\urllib\request.py", line 523, in open
    response = meth(req, response)
  File "E:\Softwares\Anaconda\envs\ML\lib\urllib\request.py", line 632, in http_response
    response = self.parent.error(
  File "E:\Softwares\Anaconda\envs\ML\lib\urllib\request.py", line 555, in error
    result = self._call_chain(*args)
  File "E:\Softwares\Anaconda\envs\ML\lib\urllib\request.py", line 494, in _call_chain
    result = func(*args)
  File "E:\Softwares\Anaconda\envs\ML\lib\urllib\request.py", line 747, in http_error_302
    return self.parent.open(new, timeout=req.timeout)
  File "E:\Softwares\Anaconda\envs\ML\lib\urllib\request.py", line 517, in open
    response = self._open(req, data)
  File "E:\Softwares\Anaconda\envs\ML\lib\urllib\request.py", line 534, in _open
    result = self._call_chain(self.handle_open, protocol, protocol +
  File "E:\Softwares\Anaconda\envs\ML\lib\urllib\request.py", line 494, in _call_chain
    result = func(*args)
  File "E:\Softwares\Anaconda\envs\ML\lib\urllib\request.py", line 1389, in https_open
    return self.do_open(http.client.HTTPSConnection, req,
  File "E:\Softwares\Anaconda\envs\ML\lib\urllib\request.py", line 1349, in do_open
    raise URLError(err)
urllib.error.URLError: <urlopen error [WinError 10060] A connection attempt failed because the connected party did not properly respond after a period of time, or established connection failed because connected host has failed to respond>
[2023-10-24 21:45:45,317:INFO:main:>>>>>> stage Data Ingestion stage started <<<<<<]
[2023-10-24 21:45:45,317:INFO:common:yaml file: config\config.yaml loaded successfully]
[2023-10-24 21:45:45,317:INFO:common:yaml file: params.yaml loaded successfully]
[2023-10-24 21:45:45,317:INFO:common:yaml file: schema.yaml loaded successfully]
[2023-10-24 21:45:45,317:INFO:common:created directory at: artifacts]
[2023-10-24 21:45:45,317:INFO:common:created directory at: artifacts/data_ingestion]
[2023-10-24 21:45:46,279:INFO:data_ingestion:artifacts/data_ingestion/data.zip download! with following info: 
Server: GitHub.com
Date: Tue, 24 Oct 2023 16:15:46 GMT
Content-Type: text/html; charset=utf-8
Vary: X-PJAX, X-PJAX-Container, Turbo-Visit, Turbo-Frame, Accept-Encoding, Accept, X-Requested-With
ETag: W/"cfd4e43563c5c881bbcdec054838a544"
Cache-Control: max-age=0, private, must-revalidate
Strict-Transport-Security: max-age=31536000; includeSubdomains; preload
X-Frame-Options: deny
X-Content-Type-Options: nosniff
X-XSS-Protection: 0
Referrer-Policy: no-referrer-when-downgrade
Content-Security-Policy: default-src 'none'; base-uri 'self'; child-src github.com/assets-cdn/worker/ gist.github.com/assets-cdn/worker/; connect-src 'self' uploads.github.com www.githubstatus.com collector.github.com raw.githubusercontent.com api.githubcopilot.com api.github.com github-cloud.s3.amazonaws.com github-production-repository-file-5c1aeb.s3.amazonaws.com github-production-upload-manifest-file-7fdce7.s3.amazonaws.com github-production-user-asset-6210df.s3.amazonaws.com cdn.optimizely.com logx.optimizely.com/v1/events objects-origin.githubusercontent.com *.actions.githubusercontent.com productionresultssa0.blob.core.windows.net/ productionresultssa1.blob.core.windows.net/ productionresultssa2.blob.core.windows.net/ productionresultssa3.blob.core.windows.net/ productionresultssa4.blob.core.windows.net/ productionresultssa5.blob.core.windows.net/ productionresultssa6.blob.core.windows.net/ productionresultssa7.blob.core.windows.net/ productionresultssa8.blob.core.windows.net/ productionresultssa9.blob.core.windows.net/ wss://*.actions.githubusercontent.com github-production-repository-image-32fea6.s3.amazonaws.com github-production-release-asset-2e65be.s3.amazonaws.com insights.github.com wss://alive.github.com; font-src github.githubassets.com; form-action 'self' github.com gist.github.com objects-origin.githubusercontent.com; frame-ancestors 'none'; frame-src viewscreen.githubusercontent.com notebooks.githubusercontent.com support.github.com; img-src 'self' data: github.githubassets.com media.githubusercontent.com camo.githubusercontent.com identicons.github.com avatars.githubusercontent.com github-cloud.s3.amazonaws.com objects.githubusercontent.com secured-user-images.githubusercontent.com/ user-images.githubusercontent.com/ private-user-images.githubusercontent.com opengraph.githubassets.com github-production-user-asset-6210df.s3.amazonaws.com customer-stories-feed.github.com spotlights-feed.github.com objects-origin.githubusercontent.com *.githubusercontent.com; manifest-src 'self'; media-src github.com user-images.githubusercontent.com/ secured-user-images.githubusercontent.com/ private-user-images.githubusercontent.com github-production-user-asset-6210df.s3.amazonaws.com; script-src github.githubassets.com; style-src 'unsafe-inline' github.githubassets.com; upgrade-insecure-requests; worker-src github.com/assets-cdn/worker/ gist.github.com/assets-cdn/worker/
Set-Cookie: _gh_sess=P1d79pM%2FXwpIqOvmCEZmADDxwQrIvMhUQcZOFmeN%2FTHlESXGvuXmJsnmhDTUJ3uDNtPXrko2x%2BrRAEZNO5iqcAHRVhsmLxh2%2FpqlTXDabBFrx6VLJXTdwB8ePx90TieCdDQdxqLw3lP03Cnn2riQ8C0ylRcVEhYMRe6O0XFSLzSCOE%2BA2YZbowhrH7OtRfDVe3vQSi8ayVWX%2FXFJPnYB5LeXjNYRfc2k4BwawTSywsX43H9vXt5NFJJ8opqSpLOU%2FOWvTY4K2FZ%2FW%2F97V%2BpewQ%3D%3D--%2Feo3Cyfi57xv4tAW--jmVZ82wX0J1UBBkupTgYsQ%3D%3D; Path=/; HttpOnly; Secure; SameSite=Lax
Set-Cookie: _octo=GH1.1.1529905759.1698164146; Path=/; Domain=github.com; Expires=Thu, 24 Oct 2024 16:15:46 GMT; Secure; SameSite=Lax
Set-Cookie: logged_in=no; Path=/; Domain=github.com; Expires=Thu, 24 Oct 2024 16:15:46 GMT; HttpOnly; Secure; SameSite=Lax
Accept-Ranges: bytes
Transfer-Encoding: chunked
X-GitHub-Request-Id: D235:2BC038:1A75EB:1D5F8C:6537EDB2
connection: close

]
[2023-10-24 21:45:46,311:ERROR:main:File is not a zip file]
Traceback (most recent call last):
  File "E:\Projects\MLOPS_MLFLOW-\main.py", line 11, in <module>
    data_ingestion.main()
  File "E:\Projects\MLOPS_MLFLOW-\src\MLProject\pipeline\stage_01_data_ingestion.py", line 18, in main
    data_ingestion.extract_zip_file()
  File "e:\projects\mlops_mlflow-\src\MLProject\components\data_ingestion.py", line 36, in extract_zip_file
    with zipfile.ZipFile(self.config.local_data_file, 'r') as zip_ref:
  File "E:\Softwares\Anaconda\envs\ML\lib\zipfile.py", line 1266, in __init__
    self._RealGetContents()
  File "E:\Softwares\Anaconda\envs\ML\lib\zipfile.py", line 1333, in _RealGetContents
    raise BadZipFile("File is not a zip file")
zipfile.BadZipFile: File is not a zip file
[2023-10-24 21:48:10,804:INFO:main:>>>>>> stage Data Ingestion stage started <<<<<<]
[2023-10-24 21:48:10,804:INFO:common:yaml file: config\config.yaml loaded successfully]
[2023-10-24 21:48:10,804:INFO:common:yaml file: params.yaml loaded successfully]
[2023-10-24 21:48:10,804:INFO:common:yaml file: schema.yaml loaded successfully]
[2023-10-24 21:48:10,820:INFO:common:created directory at: artifacts]
[2023-10-24 21:48:10,820:INFO:common:created directory at: artifacts/data_ingestion]
[2023-10-24 21:48:10,820:INFO:data_ingestion:File already exists of size: ~ 119 KB]
[2023-10-24 21:48:10,820:ERROR:main:File is not a zip file]
Traceback (most recent call last):
  File "E:\Projects\MLOPS_MLFLOW-\main.py", line 11, in <module>
    data_ingestion.main()
  File "E:\Projects\MLOPS_MLFLOW-\src\MLProject\pipeline\stage_01_data_ingestion.py", line 18, in main
    data_ingestion.extract_zip_file()
  File "e:\projects\mlops_mlflow-\src\MLProject\components\data_ingestion.py", line 36, in extract_zip_file
    with zipfile.ZipFile(self.config.local_data_file, 'r') as zip_ref:
  File "E:\Softwares\Anaconda\envs\ML\lib\zipfile.py", line 1266, in __init__
    self._RealGetContents()
  File "E:\Softwares\Anaconda\envs\ML\lib\zipfile.py", line 1333, in _RealGetContents
    raise BadZipFile("File is not a zip file")
zipfile.BadZipFile: File is not a zip file
[2023-10-24 21:48:31,990:INFO:main:>>>>>> stage Data Ingestion stage started <<<<<<]
[2023-10-24 21:48:31,990:INFO:common:yaml file: config\config.yaml loaded successfully]
[2023-10-24 21:48:31,990:INFO:common:yaml file: params.yaml loaded successfully]
[2023-10-24 21:48:32,006:INFO:common:yaml file: schema.yaml loaded successfully]
[2023-10-24 21:48:32,006:INFO:common:created directory at: artifacts]
[2023-10-24 21:48:32,006:INFO:common:created directory at: artifacts/data_ingestion]
[2023-10-24 21:48:32,006:INFO:data_ingestion:File already exists of size: ~ 119 KB]
[2023-10-24 21:48:32,006:ERROR:main:File is not a zip file]
Traceback (most recent call last):
  File "E:\Projects\MLOPS_MLFLOW-\main.py", line 11, in <module>
    data_ingestion.main()
  File "E:\Projects\MLOPS_MLFLOW-\src\MLProject\pipeline\stage_01_data_ingestion.py", line 18, in main
    data_ingestion.extract_zip_file()
  File "e:\projects\mlops_mlflow-\src\MLProject\components\data_ingestion.py", line 36, in extract_zip_file
    with zipfile.ZipFile(self.config.local_data_file, 'r') as zip_ref:
  File "E:\Softwares\Anaconda\envs\ML\lib\zipfile.py", line 1266, in __init__
    self._RealGetContents()
  File "E:\Softwares\Anaconda\envs\ML\lib\zipfile.py", line 1333, in _RealGetContents
    raise BadZipFile("File is not a zip file")
zipfile.BadZipFile: File is not a zip file
[2023-10-24 21:49:19,557:INFO:main:>>>>>> stage Data Ingestion stage started <<<<<<]
[2023-10-24 21:49:19,557:INFO:common:yaml file: config\config.yaml loaded successfully]
[2023-10-24 21:49:19,557:INFO:common:yaml file: params.yaml loaded successfully]
[2023-10-24 21:49:19,557:INFO:common:yaml file: schema.yaml loaded successfully]
[2023-10-24 21:49:19,557:INFO:common:created directory at: artifacts]
[2023-10-24 21:49:19,557:INFO:common:created directory at: artifacts/data_ingestion]
[2023-10-24 21:49:19,557:ERROR:main:<urlopen error unknown url type: e>]
Traceback (most recent call last):
  File "E:\Projects\MLOPS_MLFLOW-\main.py", line 11, in <module>
    data_ingestion.main()
  File "E:\Projects\MLOPS_MLFLOW-\src\MLProject\pipeline\stage_01_data_ingestion.py", line 17, in main
    data_ingestion.download_file()
  File "e:\projects\mlops_mlflow-\src\MLProject\components\data_ingestion.py", line 18, in download_file
    filename, headers = request.urlretrieve(
  File "E:\Softwares\Anaconda\envs\ML\lib\urllib\request.py", line 239, in urlretrieve
    with contextlib.closing(urlopen(url, data)) as fp:
  File "E:\Softwares\Anaconda\envs\ML\lib\urllib\request.py", line 214, in urlopen
    return opener.open(url, data, timeout)
  File "E:\Softwares\Anaconda\envs\ML\lib\urllib\request.py", line 517, in open
    response = self._open(req, data)
  File "E:\Softwares\Anaconda\envs\ML\lib\urllib\request.py", line 539, in _open
    return self._call_chain(self.handle_open, 'unknown',
  File "E:\Softwares\Anaconda\envs\ML\lib\urllib\request.py", line 494, in _call_chain
    result = func(*args)
  File "E:\Softwares\Anaconda\envs\ML\lib\urllib\request.py", line 1417, in unknown_open
    raise URLError('unknown url type: %s' % type)
urllib.error.URLError: <urlopen error unknown url type: e>
[2023-10-24 21:49:57,926:INFO:main:>>>>>> stage Data Ingestion stage started <<<<<<]
[2023-10-24 21:49:57,926:INFO:common:yaml file: config\config.yaml loaded successfully]
[2023-10-24 21:49:57,926:INFO:common:yaml file: params.yaml loaded successfully]
[2023-10-24 21:49:57,926:INFO:common:yaml file: schema.yaml loaded successfully]
[2023-10-24 21:49:57,926:INFO:common:created directory at: artifacts]
[2023-10-24 21:49:57,926:INFO:common:created directory at: artifacts/data_ingestion]
[2023-10-24 21:50:40,756:ERROR:main:<urlopen error [WinError 10060] A connection attempt failed because the connected party did not properly respond after a period of time, or established connection failed because connected host has failed to respond>]
Traceback (most recent call last):
  File "E:\Softwares\Anaconda\envs\ML\lib\urllib\request.py", line 1346, in do_open
    h.request(req.get_method(), req.selector, req.data, headers,
  File "E:\Softwares\Anaconda\envs\ML\lib\http\client.py", line 1285, in request
    self._send_request(method, url, body, headers, encode_chunked)
  File "E:\Softwares\Anaconda\envs\ML\lib\http\client.py", line 1331, in _send_request
    self.endheaders(body, encode_chunked=encode_chunked)
  File "E:\Softwares\Anaconda\envs\ML\lib\http\client.py", line 1280, in endheaders
    self._send_output(message_body, encode_chunked=encode_chunked)
  File "E:\Softwares\Anaconda\envs\ML\lib\http\client.py", line 1040, in _send_output
    self.send(msg)
  File "E:\Softwares\Anaconda\envs\ML\lib\http\client.py", line 980, in send
    self.connect()
  File "E:\Softwares\Anaconda\envs\ML\lib\http\client.py", line 1447, in connect
    super().connect()
  File "E:\Softwares\Anaconda\envs\ML\lib\http\client.py", line 946, in connect
    self.sock = self._create_connection(
  File "E:\Softwares\Anaconda\envs\ML\lib\socket.py", line 844, in create_connection
    raise err
  File "E:\Softwares\Anaconda\envs\ML\lib\socket.py", line 832, in create_connection
    sock.connect(sa)
TimeoutError: [WinError 10060] A connection attempt failed because the connected party did not properly respond after a period of time, or established connection failed because connected host has failed to respond

During handling of the above exception, another exception occurred:

Traceback (most recent call last):
  File "E:\Projects\MLOPS_MLFLOW-\main.py", line 11, in <module>
    data_ingestion.main()
  File "E:\Projects\MLOPS_MLFLOW-\src\MLProject\pipeline\stage_01_data_ingestion.py", line 17, in main
    data_ingestion.download_file()
  File "e:\projects\mlops_mlflow-\src\MLProject\components\data_ingestion.py", line 18, in download_file
    filename, headers = request.urlretrieve(
  File "E:\Softwares\Anaconda\envs\ML\lib\urllib\request.py", line 239, in urlretrieve
    with contextlib.closing(urlopen(url, data)) as fp:
  File "E:\Softwares\Anaconda\envs\ML\lib\urllib\request.py", line 214, in urlopen
    return opener.open(url, data, timeout)
  File "E:\Softwares\Anaconda\envs\ML\lib\urllib\request.py", line 523, in open
    response = meth(req, response)
  File "E:\Softwares\Anaconda\envs\ML\lib\urllib\request.py", line 632, in http_response
    response = self.parent.error(
  File "E:\Softwares\Anaconda\envs\ML\lib\urllib\request.py", line 555, in error
    result = self._call_chain(*args)
  File "E:\Softwares\Anaconda\envs\ML\lib\urllib\request.py", line 494, in _call_chain
    result = func(*args)
  File "E:\Softwares\Anaconda\envs\ML\lib\urllib\request.py", line 747, in http_error_302
    return self.parent.open(new, timeout=req.timeout)
  File "E:\Softwares\Anaconda\envs\ML\lib\urllib\request.py", line 517, in open
    response = self._open(req, data)
  File "E:\Softwares\Anaconda\envs\ML\lib\urllib\request.py", line 534, in _open
    result = self._call_chain(self.handle_open, protocol, protocol +
  File "E:\Softwares\Anaconda\envs\ML\lib\urllib\request.py", line 494, in _call_chain
    result = func(*args)
  File "E:\Softwares\Anaconda\envs\ML\lib\urllib\request.py", line 1389, in https_open
    return self.do_open(http.client.HTTPSConnection, req,
  File "E:\Softwares\Anaconda\envs\ML\lib\urllib\request.py", line 1349, in do_open
    raise URLError(err)
urllib.error.URLError: <urlopen error [WinError 10060] A connection attempt failed because the connected party did not properly respond after a period of time, or established connection failed because connected host has failed to respond>
[2023-10-24 21:53:25,020:INFO:main:>>>>>> stage Data Ingestion stage started <<<<<<]
[2023-10-24 21:53:25,020:INFO:common:yaml file: config\config.yaml loaded successfully]
[2023-10-24 21:53:25,020:INFO:common:yaml file: params.yaml loaded successfully]
[2023-10-24 21:53:25,020:INFO:common:yaml file: schema.yaml loaded successfully]
[2023-10-24 21:53:25,020:INFO:common:created directory at: artifacts]
[2023-10-24 21:53:25,020:INFO:common:created directory at: artifacts/data_ingestion]
[2023-10-24 21:53:25,020:ERROR:main:<urlopen error unknown url type: e>]
Traceback (most recent call last):
  File "E:\Projects\MLOPS_MLFLOW-\main.py", line 11, in <module>
    data_ingestion.main()
  File "E:\Projects\MLOPS_MLFLOW-\src\MLProject\pipeline\stage_01_data_ingestion.py", line 17, in main
    data_ingestion.download_file()
  File "e:\projects\mlops_mlflow-\src\MLProject\components\data_ingestion.py", line 18, in download_file
    filename, headers = request.urlretrieve(
  File "E:\Softwares\Anaconda\envs\ML\lib\urllib\request.py", line 239, in urlretrieve
    with contextlib.closing(urlopen(url, data)) as fp:
  File "E:\Softwares\Anaconda\envs\ML\lib\urllib\request.py", line 214, in urlopen
    return opener.open(url, data, timeout)
  File "E:\Softwares\Anaconda\envs\ML\lib\urllib\request.py", line 517, in open
    response = self._open(req, data)
  File "E:\Softwares\Anaconda\envs\ML\lib\urllib\request.py", line 539, in _open
    return self._call_chain(self.handle_open, 'unknown',
  File "E:\Softwares\Anaconda\envs\ML\lib\urllib\request.py", line 494, in _call_chain
    result = func(*args)
  File "E:\Softwares\Anaconda\envs\ML\lib\urllib\request.py", line 1417, in unknown_open
    raise URLError('unknown url type: %s' % type)
urllib.error.URLError: <urlopen error unknown url type: e>
[2023-10-24 21:57:40,535:INFO:main:>>>>>> stage Data Ingestion stage started <<<<<<]
[2023-10-24 21:57:40,535:INFO:common:yaml file: config\config.yaml loaded successfully]
[2023-10-24 21:57:40,535:INFO:common:yaml file: params.yaml loaded successfully]
[2023-10-24 21:57:40,535:INFO:common:yaml file: schema.yaml loaded successfully]
[2023-10-24 21:57:40,535:INFO:common:created directory at: artifacts]
[2023-10-24 21:57:40,535:INFO:common:created directory at: artifacts/data_ingestion]
[2023-10-24 21:57:41,586:INFO:data_ingestion:artifacts/data_ingestion/data.zip download! with following info: 
Content-Type: application/x-zip-compressed
Last-Modified: Wed, 07 Oct 2009 14:56:35 GMT
Accept-Ranges: bytes
ETag: "8013395d5e47ca1:0"
Server: Microsoft-IIS/10.0
X-Powered-By: ASP.NET
Date: Tue, 24 Oct 2023 16:27:41 GMT
Connection: close
Content-Length: 96005

]
[2023-10-24 21:57:41,600:INFO:main:>>>>>> stage Data Ingestion stage completed <<<<<<

x==========x]
[2023-10-24 21:57:57,113:INFO:main:>>>>>> stage Data Ingestion stage started <<<<<<]
[2023-10-24 21:57:57,115:INFO:common:yaml file: config\config.yaml loaded successfully]
[2023-10-24 21:57:57,116:INFO:common:yaml file: params.yaml loaded successfully]
[2023-10-24 21:57:57,118:INFO:common:yaml file: schema.yaml loaded successfully]
[2023-10-24 21:57:57,118:INFO:common:created directory at: artifacts]
[2023-10-24 21:57:57,118:INFO:common:created directory at: artifacts/data_ingestion]
[2023-10-24 21:57:58,342:INFO:data_ingestion:artifacts/data_ingestion/data.zip download! with following info: 
Content-Type: application/x-zip-compressed
Last-Modified: Wed, 07 Oct 2009 14:56:35 GMT
Accept-Ranges: bytes
ETag: "8013395d5e47ca1:0"
Server: Microsoft-IIS/10.0
X-Powered-By: ASP.NET
Date: Tue, 24 Oct 2023 16:27:58 GMT
Connection: close
Content-Length: 96005

]
[2023-10-24 21:57:58,352:INFO:main:>>>>>> stage Data Ingestion stage completed <<<<<<

x==========x]
[2023-10-24 22:46:50,323:INFO:utils:Note: NumExpr detected 16 cores but "NUMEXPR_MAX_THREADS" not set, so enforcing safe limit of 8.]
[2023-10-24 22:46:50,323:INFO:utils:NumExpr defaulting to 8 threads.]
[2023-10-24 22:46:50,972:INFO:main:>>>>>> stage Data Ingestion stage started <<<<<<]
[2023-10-24 22:46:50,976:INFO:common:yaml file: config\config.yaml loaded successfully]
[2023-10-24 22:46:50,977:INFO:common:yaml file: params.yaml loaded successfully]
[2023-10-24 22:46:50,978:INFO:common:yaml file: schema.yaml loaded successfully]
[2023-10-24 22:46:50,978:INFO:common:created directory at: artifacts]
[2023-10-24 22:46:50,979:INFO:common:created directory at: artifacts/data_ingestion]
[2023-10-24 22:46:50,979:INFO:data_ingestion:File already exists of size: ~ 94 KB]
[2023-10-24 22:46:50,982:INFO:main:>>>>>> stage Data Ingestion stage completed <<<<<<

x==========x]
[2023-10-24 22:46:50,982:INFO:main:>>>>>> stage Data Validation stage started <<<<<<]
[2023-10-24 22:46:50,985:INFO:common:yaml file: config\config.yaml loaded successfully]
[2023-10-24 22:46:50,985:INFO:common:yaml file: params.yaml loaded successfully]
[2023-10-24 22:46:50,987:INFO:common:yaml file: schema.yaml loaded successfully]
[2023-10-24 22:46:50,988:INFO:common:created directory at: artifacts]
[2023-10-24 22:46:50,988:INFO:common:created directory at: artifacts/data_validation]
[2023-10-24 22:46:50,988:ERROR:main:__init__() got an unexpected keyword argument 'STATUS_FILE']
Traceback (most recent call last):
  File "E:\Projects\MLOPS_MLFLOW-\main.py", line 23, in <module>
    data_ingestion.main()
  File "E:\Projects\MLOPS_MLFLOW-\src\MLProject\pipeline\stage_02_data_validation.py", line 14, in main
    data_validation_config = config.get_data_validation_config()
  File "e:\projects\mlops_mlflow-\src\MLProject\config\configuration.py", line 41, in get_data_validation_config
    data_validation_config = DataValidationConfig(
TypeError: __init__() got an unexpected keyword argument 'STATUS_FILE'
[2023-10-24 22:50:03,166:INFO:utils:Note: NumExpr detected 16 cores but "NUMEXPR_MAX_THREADS" not set, so enforcing safe limit of 8.]
[2023-10-24 22:50:03,166:INFO:utils:NumExpr defaulting to 8 threads.]
[2023-10-24 22:50:03,375:INFO:main:>>>>>> stage Data Ingestion stage started <<<<<<]
[2023-10-24 22:50:03,378:INFO:common:yaml file: config\config.yaml loaded successfully]
[2023-10-24 22:50:03,378:INFO:common:yaml file: params.yaml loaded successfully]
[2023-10-24 22:50:03,380:INFO:common:yaml file: schema.yaml loaded successfully]
[2023-10-24 22:50:03,380:INFO:common:created directory at: artifacts]
[2023-10-24 22:50:03,381:INFO:common:created directory at: artifacts/data_ingestion]
[2023-10-24 22:50:03,381:INFO:data_ingestion:File already exists of size: ~ 94 KB]
[2023-10-24 22:50:03,384:INFO:main:>>>>>> stage Data Ingestion stage completed <<<<<<

x==========x]
[2023-10-24 22:50:03,384:INFO:main:>>>>>> stage Data Validation stage started <<<<<<]
[2023-10-24 22:50:03,386:INFO:common:yaml file: config\config.yaml loaded successfully]
[2023-10-24 22:50:03,387:INFO:common:yaml file: params.yaml loaded successfully]
[2023-10-24 22:50:03,389:INFO:common:yaml file: schema.yaml loaded successfully]
[2023-10-24 22:50:03,389:INFO:common:created directory at: artifacts]
[2023-10-24 22:50:03,389:INFO:common:created directory at: artifacts/data_validation]
[2023-10-24 22:50:03,391:ERROR:main:[Errno 2] No such file or directory: 'artifacts/data_ingestion/winequality-red.csv']
Traceback (most recent call last):
  File "E:\Projects\MLOPS_MLFLOW-\main.py", line 23, in <module>
    data_ingestion.main()
  File "E:\Projects\MLOPS_MLFLOW-\src\MLProject\pipeline\stage_02_data_validation.py", line 16, in main
    data_validation.validate_all_columns()
  File "e:\projects\mlops_mlflow-\src\MLProject\components\data_validation.py", line 35, in validate_all_columns
    raise e
  File "e:\projects\mlops_mlflow-\src\MLProject\components\data_validation.py", line 16, in validate_all_columns
    data = pd.read_csv(self.config.unzip_data_dir)
  File "C:\Users\madhu\AppData\Roaming\Python\Python39\site-packages\pandas\io\parsers\readers.py", line 948, in read_csv
    return _read(filepath_or_buffer, kwds)
  File "C:\Users\madhu\AppData\Roaming\Python\Python39\site-packages\pandas\io\parsers\readers.py", line 611, in _read
    parser = TextFileReader(filepath_or_buffer, **kwds)
  File "C:\Users\madhu\AppData\Roaming\Python\Python39\site-packages\pandas\io\parsers\readers.py", line 1448, in __init__
    self._engine = self._make_engine(f, self.engine)
  File "C:\Users\madhu\AppData\Roaming\Python\Python39\site-packages\pandas\io\parsers\readers.py", line 1705, in _make_engine
    self.handles = get_handle(
  File "C:\Users\madhu\AppData\Roaming\Python\Python39\site-packages\pandas\io\common.py", line 863, in get_handle
    handle = open(
FileNotFoundError: [Errno 2] No such file or directory: 'artifacts/data_ingestion/winequality-red.csv'
[2023-10-24 22:55:27,333:INFO:utils:Note: NumExpr detected 16 cores but "NUMEXPR_MAX_THREADS" not set, so enforcing safe limit of 8.]
[2023-10-24 22:55:27,333:INFO:utils:NumExpr defaulting to 8 threads.]
[2023-10-24 22:55:27,547:INFO:main:>>>>>> stage Data Ingestion stage started <<<<<<]
[2023-10-24 22:55:27,554:INFO:common:yaml file: config\config.yaml loaded successfully]
[2023-10-24 22:55:27,555:INFO:common:yaml file: params.yaml loaded successfully]
[2023-10-24 22:55:27,557:INFO:common:yaml file: schema.yaml loaded successfully]
[2023-10-24 22:55:27,557:INFO:common:created directory at: artifacts]
[2023-10-24 22:55:27,557:INFO:common:created directory at: artifacts/data_ingestion]
[2023-10-24 22:55:27,557:INFO:data_ingestion:File already exists of size: ~ 94 KB]
[2023-10-24 22:55:27,561:INFO:main:>>>>>> stage Data Ingestion stage completed <<<<<<

x==========x]
[2023-10-24 22:55:27,561:INFO:main:>>>>>> stage Data Validation stage started <<<<<<]
[2023-10-24 22:55:27,563:INFO:common:yaml file: config\config.yaml loaded successfully]
[2023-10-24 22:55:27,564:INFO:common:yaml file: params.yaml loaded successfully]
[2023-10-24 22:55:27,565:INFO:common:yaml file: schema.yaml loaded successfully]
[2023-10-24 22:55:27,566:INFO:common:created directory at: artifacts]
[2023-10-24 22:55:27,566:INFO:common:created directory at: artifacts/data_validation]
[2023-10-24 22:55:27,575:INFO:main:>>>>>> stage Data Validation stage completed <<<<<<

x==========x]
[2023-10-26 00:28:48,243:INFO:utils:Note: NumExpr detected 16 cores but "NUMEXPR_MAX_THREADS" not set, so enforcing safe limit of 8.]
[2023-10-26 00:28:48,243:INFO:utils:NumExpr defaulting to 8 threads.]
[2023-10-26 00:30:50,091:INFO:utils:Note: NumExpr detected 16 cores but "NUMEXPR_MAX_THREADS" not set, so enforcing safe limit of 8.]
[2023-10-26 00:30:50,091:INFO:utils:NumExpr defaulting to 8 threads.]
[2023-10-26 00:33:02,506:INFO:utils:Note: NumExpr detected 16 cores but "NUMEXPR_MAX_THREADS" not set, so enforcing safe limit of 8.]
[2023-10-26 00:33:02,506:INFO:utils:NumExpr defaulting to 8 threads.]
[2023-10-26 00:34:13,789:INFO:utils:Note: NumExpr detected 16 cores but "NUMEXPR_MAX_THREADS" not set, so enforcing safe limit of 8.]
[2023-10-26 00:34:13,790:INFO:utils:NumExpr defaulting to 8 threads.]
[2023-10-26 00:34:15,343:INFO:main:>>>>>> stage Data Ingestion stage started <<<<<<]
[2023-10-26 00:34:15,346:INFO:common:yaml file: config\config.yaml loaded successfully]
[2023-10-26 00:34:15,350:INFO:common:yaml file: params.yaml loaded successfully]
[2023-10-26 00:34:15,355:INFO:common:yaml file: schema.yaml loaded successfully]
[2023-10-26 00:34:15,356:INFO:common:created directory at: artifacts]
[2023-10-26 00:34:15,356:INFO:common:created directory at: artifacts/data_ingestion]
[2023-10-26 00:34:15,356:INFO:data_ingestion:File already exists of size: ~ 94 KB]
[2023-10-26 00:34:15,371:INFO:main:>>>>>> stage Data Ingestion stage completed <<<<<<

x==========x]
[2023-10-26 00:34:15,372:INFO:main:>>>>>> stage Data Validation stage started <<<<<<]
[2023-10-26 00:34:15,374:INFO:common:yaml file: config\config.yaml loaded successfully]
[2023-10-26 00:34:15,375:INFO:common:yaml file: params.yaml loaded successfully]
[2023-10-26 00:34:15,377:INFO:common:yaml file: schema.yaml loaded successfully]
[2023-10-26 00:34:15,377:INFO:common:created directory at: artifacts]
[2023-10-26 00:34:15,377:INFO:common:created directory at: artifacts/data_validation]
[2023-10-26 00:34:15,392:INFO:main:>>>>>> stage Data Validation stage completed <<<<<<

x==========x]
[2023-10-26 00:34:15,392:INFO:main:>>>>>> stage Data Transformation stage started <<<<<<]
[2023-10-26 00:34:15,396:INFO:main:>>>>>> stage Data Transformation stage completed <<<<<<

x==========x]
[2023-10-26 00:34:15,396:INFO:main:>>>>>> stage Model Trainer stage started <<<<<<]
[2023-10-26 00:34:15,398:INFO:common:yaml file: config\config.yaml loaded successfully]
[2023-10-26 00:34:15,399:INFO:common:yaml file: params.yaml loaded successfully]
[2023-10-26 00:34:15,400:INFO:common:yaml file: schema.yaml loaded successfully]
[2023-10-26 00:34:15,401:INFO:common:created directory at: artifacts]
[2023-10-26 00:34:15,401:INFO:common:created directory at: artifacts/model_trainer]
[2023-10-26 00:34:15,401:ERROR:main:[Errno 2] No such file or directory: 'artifacts/data_transformation/train.csv']
Traceback (most recent call last):
  File "E:\Projects\MLOPS_MLFLOW-\main.py", line 51, in <module>
    data_ingestion.main()
  File "E:\Projects\MLOPS_MLFLOW-\src\MLProject\pipeline\stage_04_model_trainer.py", line 17, in main
    model_trainer_config.train()
  File "e:\projects\mlops_mlflow-\src\MLProject\components\model_trainer.py", line 16, in train
    train_data = pd.read_csv(self.config.train_data_path)
  File "C:\Users\madhu\AppData\Roaming\Python\Python39\site-packages\pandas\io\parsers\readers.py", line 948, in read_csv
    return _read(filepath_or_buffer, kwds)
  File "C:\Users\madhu\AppData\Roaming\Python\Python39\site-packages\pandas\io\parsers\readers.py", line 611, in _read
    parser = TextFileReader(filepath_or_buffer, **kwds)
  File "C:\Users\madhu\AppData\Roaming\Python\Python39\site-packages\pandas\io\parsers\readers.py", line 1448, in __init__
    self._engine = self._make_engine(f, self.engine)
  File "C:\Users\madhu\AppData\Roaming\Python\Python39\site-packages\pandas\io\parsers\readers.py", line 1705, in _make_engine
    self.handles = get_handle(
  File "C:\Users\madhu\AppData\Roaming\Python\Python39\site-packages\pandas\io\common.py", line 863, in get_handle
    handle = open(
FileNotFoundError: [Errno 2] No such file or directory: 'artifacts/data_transformation/train.csv'
[2023-10-26 00:37:59,222:INFO:utils:Note: NumExpr detected 16 cores but "NUMEXPR_MAX_THREADS" not set, so enforcing safe limit of 8.]
[2023-10-26 00:37:59,223:INFO:utils:NumExpr defaulting to 8 threads.]
[2023-10-26 00:38:00,697:INFO:main:>>>>>> stage Data Ingestion stage started <<<<<<]
[2023-10-26 00:38:00,699:INFO:common:yaml file: config\config.yaml loaded successfully]
[2023-10-26 00:38:00,700:INFO:common:yaml file: params.yaml loaded successfully]
[2023-10-26 00:38:00,701:INFO:common:yaml file: schema.yaml loaded successfully]
[2023-10-26 00:38:00,702:INFO:common:created directory at: artifacts]
[2023-10-26 00:38:00,702:INFO:common:created directory at: artifacts/data_ingestion]
[2023-10-26 00:38:00,702:INFO:data_ingestion:File already exists of size: ~ 94 KB]
[2023-10-26 00:38:00,705:INFO:main:>>>>>> stage Data Ingestion stage completed <<<<<<

x==========x]
[2023-10-26 00:38:00,706:INFO:main:>>>>>> stage Data Validation stage started <<<<<<]
[2023-10-26 00:38:00,708:INFO:common:yaml file: config\config.yaml loaded successfully]
[2023-10-26 00:38:00,708:INFO:common:yaml file: params.yaml loaded successfully]
[2023-10-26 00:38:00,709:INFO:common:yaml file: schema.yaml loaded successfully]
[2023-10-26 00:38:00,710:INFO:common:created directory at: artifacts]
[2023-10-26 00:38:00,710:INFO:common:created directory at: artifacts/data_validation]
[2023-10-26 00:38:00,718:INFO:main:>>>>>> stage Data Validation stage completed <<<<<<

x==========x]
[2023-10-26 00:38:00,718:INFO:main:>>>>>> stage Data Transformation stage started <<<<<<]
[2023-10-26 00:38:00,719:INFO:main:>>>>>> stage Data Transformation stage completed <<<<<<

x==========x]
[2023-10-26 00:38:00,719:INFO:main:>>>>>> stage Model Trainer stage started <<<<<<]
[2023-10-26 00:38:00,722:INFO:common:yaml file: config\config.yaml loaded successfully]
[2023-10-26 00:38:00,722:INFO:common:yaml file: params.yaml loaded successfully]
[2023-10-26 00:38:00,724:INFO:common:yaml file: schema.yaml loaded successfully]
[2023-10-26 00:38:00,724:INFO:common:created directory at: artifacts]
[2023-10-26 00:38:00,724:INFO:common:created directory at: artifacts/model_trainer]
[2023-10-26 00:38:00,724:ERROR:main:[Errno 2] No such file or directory: 'artifacts/data_transformation/train.csv']
Traceback (most recent call last):
  File "E:\Projects\MLOPS_MLFLOW-\main.py", line 51, in <module>
    data_ingestion.main()
  File "E:\Projects\MLOPS_MLFLOW-\src\MLProject\pipeline\stage_04_model_trainer.py", line 17, in main
    model_trainer_config.train()
  File "e:\projects\mlops_mlflow-\src\MLProject\components\model_trainer.py", line 16, in train
    train_data = pd.read_csv(self.config.train_data_path)
  File "C:\Users\madhu\AppData\Roaming\Python\Python39\site-packages\pandas\io\parsers\readers.py", line 948, in read_csv
    return _read(filepath_or_buffer, kwds)
  File "C:\Users\madhu\AppData\Roaming\Python\Python39\site-packages\pandas\io\parsers\readers.py", line 611, in _read
    parser = TextFileReader(filepath_or_buffer, **kwds)
  File "C:\Users\madhu\AppData\Roaming\Python\Python39\site-packages\pandas\io\parsers\readers.py", line 1448, in __init__
    self._engine = self._make_engine(f, self.engine)
  File "C:\Users\madhu\AppData\Roaming\Python\Python39\site-packages\pandas\io\parsers\readers.py", line 1705, in _make_engine
    self.handles = get_handle(
  File "C:\Users\madhu\AppData\Roaming\Python\Python39\site-packages\pandas\io\common.py", line 863, in get_handle
    handle = open(
FileNotFoundError: [Errno 2] No such file or directory: 'artifacts/data_transformation/train.csv'
[2023-10-26 00:39:24,890:INFO:utils:Note: NumExpr detected 16 cores but "NUMEXPR_MAX_THREADS" not set, so enforcing safe limit of 8.]
[2023-10-26 00:39:24,890:INFO:utils:NumExpr defaulting to 8 threads.]
[2023-10-26 00:39:26,353:INFO:main:>>>>>> stage Data Ingestion stage started <<<<<<]
[2023-10-26 00:39:26,355:INFO:common:yaml file: config\config.yaml loaded successfully]
[2023-10-26 00:39:26,356:INFO:common:yaml file: params.yaml loaded successfully]
[2023-10-26 00:39:26,357:INFO:common:yaml file: schema.yaml loaded successfully]
[2023-10-26 00:39:26,359:INFO:common:created directory at: artifacts]
[2023-10-26 00:39:26,359:INFO:common:created directory at: artifacts/data_ingestion]
[2023-10-26 00:39:26,359:INFO:data_ingestion:File already exists of size: ~ 94 KB]
[2023-10-26 00:39:26,363:INFO:main:>>>>>> stage Data Ingestion stage completed <<<<<<

x==========x]
[2023-10-26 00:39:26,363:INFO:main:>>>>>> stage Data Validation stage started <<<<<<]
[2023-10-26 00:39:26,366:INFO:common:yaml file: config\config.yaml loaded successfully]
[2023-10-26 00:39:26,366:INFO:common:yaml file: params.yaml loaded successfully]
[2023-10-26 00:39:26,368:INFO:common:yaml file: schema.yaml loaded successfully]
[2023-10-26 00:39:26,368:INFO:common:created directory at: artifacts]
[2023-10-26 00:39:26,368:INFO:common:created directory at: artifacts/data_validation]
[2023-10-26 00:39:26,375:INFO:main:>>>>>> stage Data Validation stage completed <<<<<<

x==========x]
[2023-10-26 00:39:26,377:INFO:main:>>>>>> stage Data Transformation stage started <<<<<<]
[2023-10-26 00:39:26,378:INFO:main:>>>>>> stage Data Transformation stage completed <<<<<<

x==========x]
[2023-10-26 00:39:26,378:INFO:main:>>>>>> stage Model Trainer stage started <<<<<<]
[2023-10-26 00:39:26,380:INFO:common:yaml file: config\config.yaml loaded successfully]
[2023-10-26 00:39:26,381:INFO:common:yaml file: params.yaml loaded successfully]
[2023-10-26 00:39:26,382:INFO:common:yaml file: schema.yaml loaded successfully]
[2023-10-26 00:39:26,383:INFO:common:created directory at: artifacts]
[2023-10-26 00:39:26,383:INFO:common:created directory at: artifacts/model_trainer]
[2023-10-26 00:39:26,383:ERROR:main:[Errno 2] No such file or directory: 'artifacts/data_transformation/train.csv']
Traceback (most recent call last):
  File "E:\Projects\MLOPS_MLFLOW-\main.py", line 51, in <module>
    data_ingestion.main()
  File "E:\Projects\MLOPS_MLFLOW-\src\MLProject\pipeline\stage_04_model_trainer.py", line 17, in main
    model_trainer_config.train()
  File "e:\projects\mlops_mlflow-\src\MLProject\components\model_trainer.py", line 16, in train
    train_data = pd.read_csv(self.config.train_data_path)
  File "C:\Users\madhu\AppData\Roaming\Python\Python39\site-packages\pandas\io\parsers\readers.py", line 948, in read_csv
    return _read(filepath_or_buffer, kwds)
  File "C:\Users\madhu\AppData\Roaming\Python\Python39\site-packages\pandas\io\parsers\readers.py", line 611, in _read
    parser = TextFileReader(filepath_or_buffer, **kwds)
  File "C:\Users\madhu\AppData\Roaming\Python\Python39\site-packages\pandas\io\parsers\readers.py", line 1448, in __init__
    self._engine = self._make_engine(f, self.engine)
  File "C:\Users\madhu\AppData\Roaming\Python\Python39\site-packages\pandas\io\parsers\readers.py", line 1705, in _make_engine
    self.handles = get_handle(
  File "C:\Users\madhu\AppData\Roaming\Python\Python39\site-packages\pandas\io\common.py", line 863, in get_handle
    handle = open(
FileNotFoundError: [Errno 2] No such file or directory: 'artifacts/data_transformation/train.csv'
[2023-10-26 00:41:32,517:INFO:utils:Note: NumExpr detected 16 cores but "NUMEXPR_MAX_THREADS" not set, so enforcing safe limit of 8.]
[2023-10-26 00:41:32,517:INFO:utils:NumExpr defaulting to 8 threads.]
[2023-10-26 00:41:34,020:INFO:main:>>>>>> stage Data Ingestion stage started <<<<<<]
[2023-10-26 00:41:34,023:INFO:common:yaml file: config\config.yaml loaded successfully]
[2023-10-26 00:41:34,023:INFO:common:yaml file: params.yaml loaded successfully]
[2023-10-26 00:41:34,025:INFO:common:yaml file: schema.yaml loaded successfully]
[2023-10-26 00:41:34,025:INFO:common:created directory at: artifacts]
[2023-10-26 00:41:34,025:INFO:common:created directory at: artifacts/data_ingestion]
[2023-10-26 00:41:34,026:INFO:data_ingestion:File already exists of size: ~ 94 KB]
[2023-10-26 00:41:34,031:INFO:main:>>>>>> stage Data Ingestion stage completed <<<<<<

x==========x]
[2023-10-26 00:41:34,031:INFO:main:>>>>>> stage Data Validation stage started <<<<<<]
[2023-10-26 00:41:34,033:INFO:common:yaml file: config\config.yaml loaded successfully]
[2023-10-26 00:41:34,034:INFO:common:yaml file: params.yaml loaded successfully]
[2023-10-26 00:41:34,035:INFO:common:yaml file: schema.yaml loaded successfully]
[2023-10-26 00:41:34,035:INFO:common:created directory at: artifacts]
[2023-10-26 00:41:34,035:INFO:common:created directory at: artifacts/data_validation]
[2023-10-26 00:41:34,044:INFO:main:>>>>>> stage Data Validation stage completed <<<<<<

x==========x]
[2023-10-26 00:41:34,044:INFO:main:>>>>>> stage Data Transformation stage started <<<<<<]
[2023-10-26 00:41:34,047:INFO:main:>>>>>> stage Data Transformation stage completed <<<<<<

x==========x]
[2023-10-26 00:41:34,048:INFO:main:>>>>>> stage Model Trainer stage started <<<<<<]
[2023-10-26 00:41:34,050:INFO:common:yaml file: config\config.yaml loaded successfully]
[2023-10-26 00:41:34,050:INFO:common:yaml file: params.yaml loaded successfully]
[2023-10-26 00:41:34,052:INFO:common:yaml file: schema.yaml loaded successfully]
[2023-10-26 00:41:34,052:INFO:common:created directory at: artifacts]
[2023-10-26 00:41:34,052:INFO:common:created directory at: artifacts/model_trainer]
[2023-10-26 00:41:34,053:ERROR:main:[Errno 2] No such file or directory: 'artifacts/data_transformation/train.csv']
Traceback (most recent call last):
  File "E:\Projects\MLOPS_MLFLOW-\main.py", line 51, in <module>
    data_ingestion.main()
  File "E:\Projects\MLOPS_MLFLOW-\src\MLProject\pipeline\stage_04_model_trainer.py", line 17, in main
    model_trainer_config.train()
  File "e:\projects\mlops_mlflow-\src\MLProject\components\model_trainer.py", line 16, in train
    train_data = pd.read_csv(self.config.train_data_path)
  File "C:\Users\madhu\AppData\Roaming\Python\Python39\site-packages\pandas\io\parsers\readers.py", line 948, in read_csv
    return _read(filepath_or_buffer, kwds)
  File "C:\Users\madhu\AppData\Roaming\Python\Python39\site-packages\pandas\io\parsers\readers.py", line 611, in _read
    parser = TextFileReader(filepath_or_buffer, **kwds)
  File "C:\Users\madhu\AppData\Roaming\Python\Python39\site-packages\pandas\io\parsers\readers.py", line 1448, in __init__
    self._engine = self._make_engine(f, self.engine)
  File "C:\Users\madhu\AppData\Roaming\Python\Python39\site-packages\pandas\io\parsers\readers.py", line 1705, in _make_engine
    self.handles = get_handle(
  File "C:\Users\madhu\AppData\Roaming\Python\Python39\site-packages\pandas\io\common.py", line 863, in get_handle
    handle = open(
FileNotFoundError: [Errno 2] No such file or directory: 'artifacts/data_transformation/train.csv'
[2023-10-26 00:53:29,651:INFO:utils:Note: NumExpr detected 16 cores but "NUMEXPR_MAX_THREADS" not set, so enforcing safe limit of 8.]
[2023-10-26 00:53:29,651:INFO:utils:NumExpr defaulting to 8 threads.]
[2023-10-26 00:53:31,122:INFO:main:>>>>>> stage Data Ingestion stage started <<<<<<]
[2023-10-26 00:53:31,124:INFO:common:yaml file: config\config.yaml loaded successfully]
[2023-10-26 00:53:31,125:INFO:common:yaml file: params.yaml loaded successfully]
[2023-10-26 00:53:31,126:INFO:common:yaml file: schema.yaml loaded successfully]
[2023-10-26 00:53:31,127:INFO:common:created directory at: artifacts]
[2023-10-26 00:53:31,127:INFO:common:created directory at: artifacts/data_ingestion]
[2023-10-26 00:53:31,127:INFO:data_ingestion:File already exists of size: ~ 94 KB]
[2023-10-26 00:53:31,131:INFO:main:>>>>>> stage Data Ingestion stage completed <<<<<<

x==========x]
[2023-10-26 00:53:31,131:INFO:main:>>>>>> stage Data Validation stage started <<<<<<]
[2023-10-26 00:53:31,133:INFO:common:yaml file: config\config.yaml loaded successfully]
[2023-10-26 00:53:31,134:INFO:common:yaml file: params.yaml loaded successfully]
[2023-10-26 00:53:31,135:INFO:common:yaml file: schema.yaml loaded successfully]
[2023-10-26 00:53:31,136:INFO:common:created directory at: artifacts]
[2023-10-26 00:53:31,137:INFO:common:created directory at: artifacts/data_validation]
[2023-10-26 00:53:31,144:INFO:main:>>>>>> stage Data Validation stage completed <<<<<<

x==========x]
[2023-10-26 00:53:31,145:INFO:main:>>>>>> stage Data Transformation stage started <<<<<<]
[2023-10-26 00:53:31,145:INFO:main:>>>>>> stage Data Transformation stage completed <<<<<<

x==========x]
[2023-10-26 00:53:31,146:INFO:main:>>>>>> stage Model Trainer stage started <<<<<<]
[2023-10-26 00:53:31,148:INFO:common:yaml file: config\config.yaml loaded successfully]
[2023-10-26 00:53:31,149:INFO:common:yaml file: params.yaml loaded successfully]
[2023-10-26 00:53:31,150:INFO:common:yaml file: schema.yaml loaded successfully]
[2023-10-26 00:53:31,150:INFO:common:created directory at: artifacts]
[2023-10-26 00:53:31,151:INFO:common:created directory at: artifacts/model_trainer]
[2023-10-26 00:53:31,151:ERROR:main:[Errno 2] No such file or directory: 'artifacts/data_transformation/train.csv']
Traceback (most recent call last):
  File "E:\Projects\MLOPS_MLFLOW-\main.py", line 51, in <module>
    data_ingestion.main()
  File "E:\Projects\MLOPS_MLFLOW-\src\MLProject\pipeline\stage_04_model_trainer.py", line 17, in main
    model_trainer_config.train()
  File "e:\projects\mlops_mlflow-\src\MLProject\components\model_trainer.py", line 16, in train
    train_data = pd.read_csv(self.config.train_data_path)
  File "C:\Users\madhu\AppData\Roaming\Python\Python39\site-packages\pandas\io\parsers\readers.py", line 948, in read_csv
    return _read(filepath_or_buffer, kwds)
  File "C:\Users\madhu\AppData\Roaming\Python\Python39\site-packages\pandas\io\parsers\readers.py", line 611, in _read
    parser = TextFileReader(filepath_or_buffer, **kwds)
  File "C:\Users\madhu\AppData\Roaming\Python\Python39\site-packages\pandas\io\parsers\readers.py", line 1448, in __init__
    self._engine = self._make_engine(f, self.engine)
  File "C:\Users\madhu\AppData\Roaming\Python\Python39\site-packages\pandas\io\parsers\readers.py", line 1705, in _make_engine
    self.handles = get_handle(
  File "C:\Users\madhu\AppData\Roaming\Python\Python39\site-packages\pandas\io\common.py", line 863, in get_handle
    handle = open(
FileNotFoundError: [Errno 2] No such file or directory: 'artifacts/data_transformation/train.csv'
[2023-10-26 00:54:34,253:INFO:utils:Note: NumExpr detected 16 cores but "NUMEXPR_MAX_THREADS" not set, so enforcing safe limit of 8.]
[2023-10-26 00:54:34,253:INFO:utils:NumExpr defaulting to 8 threads.]
[2023-10-26 00:54:35,715:INFO:main:>>>>>> stage Data Ingestion stage started <<<<<<]
[2023-10-26 00:54:35,717:INFO:common:yaml file: config\config.yaml loaded successfully]
[2023-10-26 00:54:35,718:INFO:common:yaml file: params.yaml loaded successfully]
[2023-10-26 00:54:35,719:INFO:common:yaml file: schema.yaml loaded successfully]
[2023-10-26 00:54:35,720:INFO:common:created directory at: artifacts]
[2023-10-26 00:54:35,720:INFO:common:created directory at: artifacts/data_ingestion]
[2023-10-26 00:54:35,720:INFO:data_ingestion:File already exists of size: ~ 94 KB]
[2023-10-26 00:54:35,724:INFO:main:>>>>>> stage Data Ingestion stage completed <<<<<<

x==========x]
[2023-10-26 00:54:35,724:INFO:main:>>>>>> stage Data Validation stage started <<<<<<]
[2023-10-26 00:54:35,726:INFO:common:yaml file: config\config.yaml loaded successfully]
[2023-10-26 00:54:35,726:INFO:common:yaml file: params.yaml loaded successfully]
[2023-10-26 00:54:35,728:INFO:common:yaml file: schema.yaml loaded successfully]
[2023-10-26 00:54:35,728:INFO:common:created directory at: artifacts]
[2023-10-26 00:54:35,728:INFO:common:created directory at: artifacts/data_validation]
[2023-10-26 00:54:35,736:INFO:main:>>>>>> stage Data Validation stage completed <<<<<<

x==========x]
[2023-10-26 00:54:35,737:INFO:main:>>>>>> stage Data Transformation stage started <<<<<<]
[2023-10-26 00:54:35,737:INFO:main:>>>>>> stage Data Transformation stage completed <<<<<<

x==========x]
[2023-10-26 00:54:35,738:INFO:main:>>>>>> stage Model Trainer stage started <<<<<<]
[2023-10-26 00:54:35,740:INFO:common:yaml file: config\config.yaml loaded successfully]
[2023-10-26 00:54:35,741:INFO:common:yaml file: params.yaml loaded successfully]
[2023-10-26 00:54:35,742:INFO:common:yaml file: schema.yaml loaded successfully]
[2023-10-26 00:54:35,743:INFO:common:created directory at: artifacts]
[2023-10-26 00:54:35,743:INFO:common:created directory at: artifacts/model_trainer]
[2023-10-26 00:54:35,744:ERROR:main:[Errno 2] No such file or directory: 'artifacts/data_transformation/train.csv']
Traceback (most recent call last):
  File "E:\Projects\MLOPS_MLFLOW-\main.py", line 51, in <module>
    data_ingestion.main()
  File "E:\Projects\MLOPS_MLFLOW-\src\MLProject\pipeline\stage_04_model_trainer.py", line 17, in main
    model_trainer_config.train()
  File "e:\projects\mlops_mlflow-\src\MLProject\components\model_trainer.py", line 16, in train
    train_data = pd.read_csv(self.config.train_data_path)
  File "C:\Users\madhu\AppData\Roaming\Python\Python39\site-packages\pandas\io\parsers\readers.py", line 948, in read_csv
    return _read(filepath_or_buffer, kwds)
  File "C:\Users\madhu\AppData\Roaming\Python\Python39\site-packages\pandas\io\parsers\readers.py", line 611, in _read
    parser = TextFileReader(filepath_or_buffer, **kwds)
  File "C:\Users\madhu\AppData\Roaming\Python\Python39\site-packages\pandas\io\parsers\readers.py", line 1448, in __init__
    self._engine = self._make_engine(f, self.engine)
  File "C:\Users\madhu\AppData\Roaming\Python\Python39\site-packages\pandas\io\parsers\readers.py", line 1705, in _make_engine
    self.handles = get_handle(
  File "C:\Users\madhu\AppData\Roaming\Python\Python39\site-packages\pandas\io\common.py", line 863, in get_handle
    handle = open(
FileNotFoundError: [Errno 2] No such file or directory: 'artifacts/data_transformation/train.csv'
[2023-10-26 00:56:19,913:INFO:utils:Note: NumExpr detected 16 cores but "NUMEXPR_MAX_THREADS" not set, so enforcing safe limit of 8.]
[2023-10-26 00:56:19,914:INFO:utils:NumExpr defaulting to 8 threads.]
[2023-10-26 00:56:21,414:INFO:main:>>>>>> stage Data Ingestion stage started <<<<<<]
[2023-10-26 00:56:21,416:INFO:common:yaml file: config\config.yaml loaded successfully]
[2023-10-26 00:56:21,417:INFO:common:yaml file: params.yaml loaded successfully]
[2023-10-26 00:56:21,418:INFO:common:yaml file: schema.yaml loaded successfully]
[2023-10-26 00:56:21,419:INFO:common:created directory at: artifacts]
[2023-10-26 00:56:21,419:INFO:common:created directory at: artifacts/data_ingestion]
[2023-10-26 00:56:21,419:INFO:data_ingestion:File already exists of size: ~ 94 KB]
[2023-10-26 00:56:21,423:INFO:main:>>>>>> stage Data Ingestion stage completed <<<<<<

x==========x]
[2023-10-26 00:56:21,423:INFO:main:>>>>>> stage Data Validation stage started <<<<<<]
[2023-10-26 00:56:21,425:INFO:common:yaml file: config\config.yaml loaded successfully]
[2023-10-26 00:56:21,426:INFO:common:yaml file: params.yaml loaded successfully]
[2023-10-26 00:56:21,428:INFO:common:yaml file: schema.yaml loaded successfully]
[2023-10-26 00:56:21,428:INFO:common:created directory at: artifacts]
[2023-10-26 00:56:21,428:INFO:common:created directory at: artifacts/data_validation]
[2023-10-26 00:56:21,436:INFO:main:>>>>>> stage Data Validation stage completed <<<<<<

x==========x]
[2023-10-26 00:56:21,437:INFO:main:>>>>>> stage Data Transformation stage started <<<<<<]
[2023-10-26 00:56:21,438:INFO:main:>>>>>> stage Data Transformation stage completed <<<<<<

x==========x]
[2023-10-26 00:56:21,438:INFO:main:>>>>>> stage Model Trainer stage started <<<<<<]
[2023-10-26 00:56:21,441:INFO:common:yaml file: config\config.yaml loaded successfully]
[2023-10-26 00:56:21,441:INFO:common:yaml file: params.yaml loaded successfully]
[2023-10-26 00:56:21,443:INFO:common:yaml file: schema.yaml loaded successfully]
[2023-10-26 00:56:21,443:INFO:common:created directory at: artifacts]
[2023-10-26 00:56:21,444:INFO:common:created directory at: artifacts/model_trainer]
[2023-10-26 00:56:21,444:ERROR:main:[Errno 2] No such file or directory: 'artifacts/data_transformation/train.csv']
Traceback (most recent call last):
  File "E:\Projects\MLOPS_MLFLOW-\main.py", line 51, in <module>
    data_ingestion.main()
  File "E:\Projects\MLOPS_MLFLOW-\src\MLProject\pipeline\stage_04_model_trainer.py", line 17, in main
    model_trainer_config.train()
  File "e:\projects\mlops_mlflow-\src\MLProject\components\model_trainer.py", line 16, in train
    train_data = pd.read_csv(self.config.train_data_path)
  File "C:\Users\madhu\AppData\Roaming\Python\Python39\site-packages\pandas\io\parsers\readers.py", line 948, in read_csv
    return _read(filepath_or_buffer, kwds)
  File "C:\Users\madhu\AppData\Roaming\Python\Python39\site-packages\pandas\io\parsers\readers.py", line 611, in _read
    parser = TextFileReader(filepath_or_buffer, **kwds)
  File "C:\Users\madhu\AppData\Roaming\Python\Python39\site-packages\pandas\io\parsers\readers.py", line 1448, in __init__
    self._engine = self._make_engine(f, self.engine)
  File "C:\Users\madhu\AppData\Roaming\Python\Python39\site-packages\pandas\io\parsers\readers.py", line 1705, in _make_engine
    self.handles = get_handle(
  File "C:\Users\madhu\AppData\Roaming\Python\Python39\site-packages\pandas\io\common.py", line 863, in get_handle
    handle = open(
FileNotFoundError: [Errno 2] No such file or directory: 'artifacts/data_transformation/train.csv'
[2023-10-26 00:57:37,519:INFO:utils:Note: NumExpr detected 16 cores but "NUMEXPR_MAX_THREADS" not set, so enforcing safe limit of 8.]
[2023-10-26 00:57:37,519:INFO:utils:NumExpr defaulting to 8 threads.]
[2023-10-26 00:57:38,983:INFO:main:>>>>>> stage Data Ingestion stage started <<<<<<]
[2023-10-26 00:57:38,986:INFO:common:yaml file: config\config.yaml loaded successfully]
[2023-10-26 00:57:38,986:INFO:common:yaml file: params.yaml loaded successfully]
[2023-10-26 00:57:38,988:INFO:common:yaml file: schema.yaml loaded successfully]
[2023-10-26 00:57:38,988:INFO:common:created directory at: artifacts]
[2023-10-26 00:57:38,988:INFO:common:created directory at: artifacts/data_ingestion]
[2023-10-26 00:57:38,988:INFO:data_ingestion:File already exists of size: ~ 94 KB]
[2023-10-26 00:57:38,992:INFO:main:>>>>>> stage Data Ingestion stage completed <<<<<<

x==========x]
[2023-10-26 00:57:38,992:INFO:main:>>>>>> stage Data Validation stage started <<<<<<]
[2023-10-26 00:57:38,994:INFO:common:yaml file: config\config.yaml loaded successfully]
[2023-10-26 00:57:38,995:INFO:common:yaml file: params.yaml loaded successfully]
[2023-10-26 00:57:38,996:INFO:common:yaml file: schema.yaml loaded successfully]
[2023-10-26 00:57:38,997:INFO:common:created directory at: artifacts]
[2023-10-26 00:57:38,997:INFO:common:created directory at: artifacts/data_validation]
[2023-10-26 00:57:39,005:INFO:main:>>>>>> stage Data Validation stage completed <<<<<<

x==========x]
[2023-10-26 00:57:39,005:INFO:main:>>>>>> stage Data Transformation stage started <<<<<<]
[2023-10-26 00:57:39,006:INFO:main:>>>>>> stage Data Transformation stage completed <<<<<<

x==========x]
[2023-10-26 00:57:39,006:INFO:main:>>>>>> stage Model Trainer stage started <<<<<<]
[2023-10-26 00:57:39,008:INFO:common:yaml file: config\config.yaml loaded successfully]
[2023-10-26 00:57:39,009:INFO:common:yaml file: params.yaml loaded successfully]
[2023-10-26 00:57:39,011:INFO:common:yaml file: schema.yaml loaded successfully]
[2023-10-26 00:57:39,011:INFO:common:created directory at: artifacts]
[2023-10-26 00:57:39,012:INFO:common:created directory at: artifacts/model_trainer]
[2023-10-26 00:57:39,012:ERROR:main:[Errno 2] No such file or directory: 'artifacts/data_transformation/train.csv']
Traceback (most recent call last):
  File "E:\Projects\MLOPS_MLFLOW-\main.py", line 51, in <module>
    data_ingestion.main()
  File "E:\Projects\MLOPS_MLFLOW-\src\MLProject\pipeline\stage_04_model_trainer.py", line 17, in main
    model_trainer_config.train()
  File "e:\projects\mlops_mlflow-\src\MLProject\components\model_trainer.py", line 16, in train
    train_data = pd.read_csv(self.config.train_data_path)
  File "C:\Users\madhu\AppData\Roaming\Python\Python39\site-packages\pandas\io\parsers\readers.py", line 948, in read_csv
    return _read(filepath_or_buffer, kwds)
  File "C:\Users\madhu\AppData\Roaming\Python\Python39\site-packages\pandas\io\parsers\readers.py", line 611, in _read
    parser = TextFileReader(filepath_or_buffer, **kwds)
  File "C:\Users\madhu\AppData\Roaming\Python\Python39\site-packages\pandas\io\parsers\readers.py", line 1448, in __init__
    self._engine = self._make_engine(f, self.engine)
  File "C:\Users\madhu\AppData\Roaming\Python\Python39\site-packages\pandas\io\parsers\readers.py", line 1705, in _make_engine
    self.handles = get_handle(
  File "C:\Users\madhu\AppData\Roaming\Python\Python39\site-packages\pandas\io\common.py", line 863, in get_handle
    handle = open(
FileNotFoundError: [Errno 2] No such file or directory: 'artifacts/data_transformation/train.csv'
[2023-10-26 00:58:07,822:INFO:utils:Note: NumExpr detected 16 cores but "NUMEXPR_MAX_THREADS" not set, so enforcing safe limit of 8.]
[2023-10-26 00:58:07,822:INFO:utils:NumExpr defaulting to 8 threads.]
[2023-10-26 00:58:09,296:INFO:main:>>>>>> stage Data Ingestion stage started <<<<<<]
[2023-10-26 00:58:09,300:INFO:common:yaml file: config\config.yaml loaded successfully]
[2023-10-26 00:58:09,300:INFO:common:yaml file: params.yaml loaded successfully]
[2023-10-26 00:58:09,302:INFO:common:yaml file: schema.yaml loaded successfully]
[2023-10-26 00:58:09,302:INFO:common:created directory at: artifacts]
[2023-10-26 00:58:09,302:INFO:common:created directory at: artifacts/data_ingestion]
[2023-10-26 00:58:09,302:INFO:data_ingestion:File already exists of size: ~ 94 KB]
[2023-10-26 00:58:09,306:INFO:main:>>>>>> stage Data Ingestion stage completed <<<<<<

x==========x]
[2023-10-26 00:58:09,306:INFO:main:>>>>>> stage Data Validation stage started <<<<<<]
[2023-10-26 00:58:09,308:INFO:common:yaml file: config\config.yaml loaded successfully]
[2023-10-26 00:58:09,309:INFO:common:yaml file: params.yaml loaded successfully]
[2023-10-26 00:58:09,310:INFO:common:yaml file: schema.yaml loaded successfully]
[2023-10-26 00:58:09,311:INFO:common:created directory at: artifacts]
[2023-10-26 00:58:09,311:INFO:common:created directory at: artifacts/data_validation]
[2023-10-26 00:58:09,320:INFO:main:>>>>>> stage Data Validation stage completed <<<<<<

x==========x]
[2023-10-26 00:58:09,320:INFO:main:>>>>>> stage Data Transformation stage started <<<<<<]
[2023-10-26 00:58:09,320:INFO:main:>>>>>> stage Data Transformation stage completed <<<<<<

x==========x]
[2023-10-26 00:58:09,320:INFO:main:>>>>>> stage Model Trainer stage started <<<<<<]
[2023-10-26 00:58:09,323:INFO:common:yaml file: config\config.yaml loaded successfully]
[2023-10-26 00:58:09,323:INFO:common:yaml file: params.yaml loaded successfully]
[2023-10-26 00:58:09,325:INFO:common:yaml file: schema.yaml loaded successfully]
[2023-10-26 00:58:09,325:INFO:common:created directory at: artifacts]
[2023-10-26 00:58:09,326:INFO:common:created directory at: artifacts/model_trainer]
[2023-10-26 00:58:09,326:ERROR:main:[Errno 2] No such file or directory: 'artifacts/data_transformation/train.csv']
Traceback (most recent call last):
  File "E:\Projects\MLOPS_MLFLOW-\main.py", line 51, in <module>
    data_ingestion.main()
  File "E:\Projects\MLOPS_MLFLOW-\src\MLProject\pipeline\stage_04_model_trainer.py", line 17, in main
    model_trainer_config.train()
  File "e:\projects\mlops_mlflow-\src\MLProject\components\model_trainer.py", line 16, in train
    train_data = pd.read_csv(self.config.train_data_path)
  File "C:\Users\madhu\AppData\Roaming\Python\Python39\site-packages\pandas\io\parsers\readers.py", line 948, in read_csv
    return _read(filepath_or_buffer, kwds)
  File "C:\Users\madhu\AppData\Roaming\Python\Python39\site-packages\pandas\io\parsers\readers.py", line 611, in _read
    parser = TextFileReader(filepath_or_buffer, **kwds)
  File "C:\Users\madhu\AppData\Roaming\Python\Python39\site-packages\pandas\io\parsers\readers.py", line 1448, in __init__
    self._engine = self._make_engine(f, self.engine)
  File "C:\Users\madhu\AppData\Roaming\Python\Python39\site-packages\pandas\io\parsers\readers.py", line 1705, in _make_engine
    self.handles = get_handle(
  File "C:\Users\madhu\AppData\Roaming\Python\Python39\site-packages\pandas\io\common.py", line 863, in get_handle
    handle = open(
FileNotFoundError: [Errno 2] No such file or directory: 'artifacts/data_transformation/train.csv'
[2023-10-26 00:59:36,195:INFO:utils:Note: NumExpr detected 16 cores but "NUMEXPR_MAX_THREADS" not set, so enforcing safe limit of 8.]
[2023-10-26 00:59:36,195:INFO:utils:NumExpr defaulting to 8 threads.]
[2023-10-26 00:59:37,676:INFO:main:>>>>>> stage Data Ingestion stage started <<<<<<]
[2023-10-26 00:59:37,678:INFO:common:yaml file: config\config.yaml loaded successfully]
[2023-10-26 00:59:37,678:INFO:common:yaml file: params.yaml loaded successfully]
[2023-10-26 00:59:37,680:INFO:common:yaml file: schema.yaml loaded successfully]
[2023-10-26 00:59:37,680:INFO:common:created directory at: artifacts]
[2023-10-26 00:59:37,680:INFO:common:created directory at: artifacts/data_ingestion]
[2023-10-26 00:59:37,680:INFO:data_ingestion:File already exists of size: ~ 94 KB]
[2023-10-26 00:59:37,684:INFO:main:>>>>>> stage Data Ingestion stage completed <<<<<<

x==========x]
[2023-10-26 00:59:37,684:INFO:main:>>>>>> stage Data Validation stage started <<<<<<]
[2023-10-26 00:59:37,686:INFO:common:yaml file: config\config.yaml loaded successfully]
[2023-10-26 00:59:37,688:INFO:common:yaml file: params.yaml loaded successfully]
[2023-10-26 00:59:37,689:INFO:common:yaml file: schema.yaml loaded successfully]
[2023-10-26 00:59:37,690:INFO:common:created directory at: artifacts]
[2023-10-26 00:59:37,690:INFO:common:created directory at: artifacts/data_validation]
[2023-10-26 00:59:37,698:INFO:main:>>>>>> stage Data Validation stage completed <<<<<<

x==========x]
[2023-10-26 00:59:37,698:INFO:main:>>>>>> stage Data Transformation stage started <<<<<<]
[2023-10-26 00:59:37,699:INFO:main:>>>>>> stage Data Transformation stage completed <<<<<<

x==========x]
[2023-10-26 00:59:37,699:INFO:main:>>>>>> stage Model Trainer stage started <<<<<<]
[2023-10-26 00:59:37,701:INFO:common:yaml file: config\config.yaml loaded successfully]
[2023-10-26 00:59:37,702:INFO:common:yaml file: params.yaml loaded successfully]
[2023-10-26 00:59:37,703:INFO:common:yaml file: schema.yaml loaded successfully]
[2023-10-26 00:59:37,704:INFO:common:created directory at: artifacts]
[2023-10-26 00:59:37,704:INFO:common:created directory at: artifacts/model_trainer]
[2023-10-26 00:59:37,704:ERROR:main:[Errno 2] No such file or directory: 'artifacts/data_transformation/train.csv']
Traceback (most recent call last):
  File "E:\Projects\MLOPS_MLFLOW-\main.py", line 51, in <module>
    data_ingestion.main()
  File "E:\Projects\MLOPS_MLFLOW-\src\MLProject\pipeline\stage_04_model_trainer.py", line 17, in main
    model_trainer_config.train()
  File "e:\projects\mlops_mlflow-\src\MLProject\components\model_trainer.py", line 16, in train
    train_data = pd.read_csv(self.config.train_data_path)
  File "C:\Users\madhu\AppData\Roaming\Python\Python39\site-packages\pandas\io\parsers\readers.py", line 948, in read_csv
    return _read(filepath_or_buffer, kwds)
  File "C:\Users\madhu\AppData\Roaming\Python\Python39\site-packages\pandas\io\parsers\readers.py", line 611, in _read
    parser = TextFileReader(filepath_or_buffer, **kwds)
  File "C:\Users\madhu\AppData\Roaming\Python\Python39\site-packages\pandas\io\parsers\readers.py", line 1448, in __init__
    self._engine = self._make_engine(f, self.engine)
  File "C:\Users\madhu\AppData\Roaming\Python\Python39\site-packages\pandas\io\parsers\readers.py", line 1705, in _make_engine
    self.handles = get_handle(
  File "C:\Users\madhu\AppData\Roaming\Python\Python39\site-packages\pandas\io\common.py", line 863, in get_handle
    handle = open(
FileNotFoundError: [Errno 2] No such file or directory: 'artifacts/data_transformation/train.csv'
[2023-10-26 01:00:12,596:INFO:utils:Note: NumExpr detected 16 cores but "NUMEXPR_MAX_THREADS" not set, so enforcing safe limit of 8.]
[2023-10-26 01:00:12,596:INFO:utils:NumExpr defaulting to 8 threads.]
[2023-10-26 01:00:14,076:INFO:main:>>>>>> stage Data Ingestion stage started <<<<<<]
[2023-10-26 01:00:14,078:INFO:common:yaml file: config\config.yaml loaded successfully]
[2023-10-26 01:00:14,079:INFO:common:yaml file: params.yaml loaded successfully]
[2023-10-26 01:00:14,080:INFO:common:yaml file: schema.yaml loaded successfully]
[2023-10-26 01:00:14,081:INFO:common:created directory at: artifacts]
[2023-10-26 01:00:14,081:INFO:common:created directory at: artifacts/data_ingestion]
[2023-10-26 01:00:14,081:INFO:data_ingestion:File already exists of size: ~ 94 KB]
[2023-10-26 01:00:14,085:INFO:main:>>>>>> stage Data Ingestion stage completed <<<<<<

x==========x]
[2023-10-26 01:00:14,085:INFO:main:>>>>>> stage Data Validation stage started <<<<<<]
[2023-10-26 01:00:14,087:INFO:common:yaml file: config\config.yaml loaded successfully]
[2023-10-26 01:00:14,088:INFO:common:yaml file: params.yaml loaded successfully]
[2023-10-26 01:00:14,090:INFO:common:yaml file: schema.yaml loaded successfully]
[2023-10-26 01:00:14,090:INFO:common:created directory at: artifacts]
[2023-10-26 01:00:14,090:INFO:common:created directory at: artifacts/data_validation]
[2023-10-26 01:00:14,098:INFO:main:>>>>>> stage Data Validation stage completed <<<<<<

x==========x]
[2023-10-26 01:00:14,098:INFO:main:>>>>>> stage Data Transformation stage started <<<<<<]
[2023-10-26 01:00:14,099:INFO:main:>>>>>> stage Data Transformation stage completed <<<<<<

x==========x]
[2023-10-26 01:00:14,099:INFO:main:>>>>>> stage Model Trainer stage started <<<<<<]
[2023-10-26 01:00:14,101:INFO:common:yaml file: config\config.yaml loaded successfully]
[2023-10-26 01:00:14,102:INFO:common:yaml file: params.yaml loaded successfully]
[2023-10-26 01:00:14,104:INFO:common:yaml file: schema.yaml loaded successfully]
[2023-10-26 01:00:14,104:INFO:common:created directory at: artifacts]
[2023-10-26 01:00:14,104:INFO:common:created directory at: artifacts/model_trainer]
[2023-10-26 01:00:14,105:ERROR:main:[Errno 2] No such file or directory: 'artifacts/data_transformation/train.csv']
Traceback (most recent call last):
  File "E:\Projects\MLOPS_MLFLOW-\main.py", line 51, in <module>
    data_ingestion.main()
  File "E:\Projects\MLOPS_MLFLOW-\src\MLProject\pipeline\stage_04_model_trainer.py", line 17, in main
    model_trainer_config.train()
  File "e:\projects\mlops_mlflow-\src\MLProject\components\model_trainer.py", line 16, in train
    train_data = pd.read_csv(self.config.train_data_path)
  File "C:\Users\madhu\AppData\Roaming\Python\Python39\site-packages\pandas\io\parsers\readers.py", line 948, in read_csv
    return _read(filepath_or_buffer, kwds)
  File "C:\Users\madhu\AppData\Roaming\Python\Python39\site-packages\pandas\io\parsers\readers.py", line 611, in _read
    parser = TextFileReader(filepath_or_buffer, **kwds)
  File "C:\Users\madhu\AppData\Roaming\Python\Python39\site-packages\pandas\io\parsers\readers.py", line 1448, in __init__
    self._engine = self._make_engine(f, self.engine)
  File "C:\Users\madhu\AppData\Roaming\Python\Python39\site-packages\pandas\io\parsers\readers.py", line 1705, in _make_engine
    self.handles = get_handle(
  File "C:\Users\madhu\AppData\Roaming\Python\Python39\site-packages\pandas\io\common.py", line 863, in get_handle
    handle = open(
FileNotFoundError: [Errno 2] No such file or directory: 'artifacts/data_transformation/train.csv'
[2023-10-26 01:01:32,784:INFO:utils:Note: NumExpr detected 16 cores but "NUMEXPR_MAX_THREADS" not set, so enforcing safe limit of 8.]
[2023-10-26 01:01:32,785:INFO:utils:NumExpr defaulting to 8 threads.]
[2023-10-26 01:01:34,269:INFO:main:>>>>>> stage Data Ingestion stage started <<<<<<]
[2023-10-26 01:01:34,272:INFO:common:yaml file: config\config.yaml loaded successfully]
[2023-10-26 01:01:34,273:INFO:common:yaml file: params.yaml loaded successfully]
[2023-10-26 01:01:34,274:INFO:common:yaml file: schema.yaml loaded successfully]
[2023-10-26 01:01:34,274:INFO:common:created directory at: artifacts]
[2023-10-26 01:01:34,275:INFO:common:created directory at: artifacts/data_ingestion]
[2023-10-26 01:01:34,275:INFO:data_ingestion:File already exists of size: ~ 94 KB]
[2023-10-26 01:01:34,278:INFO:main:>>>>>> stage Data Ingestion stage completed <<<<<<

x==========x]
[2023-10-26 01:01:34,279:INFO:main:>>>>>> stage Data Validation stage started <<<<<<]
[2023-10-26 01:01:34,281:INFO:common:yaml file: config\config.yaml loaded successfully]
[2023-10-26 01:01:34,282:INFO:common:yaml file: params.yaml loaded successfully]
[2023-10-26 01:01:34,283:INFO:common:yaml file: schema.yaml loaded successfully]
[2023-10-26 01:01:34,284:INFO:common:created directory at: artifacts]
[2023-10-26 01:01:34,284:INFO:common:created directory at: artifacts/data_validation]
[2023-10-26 01:01:34,291:ERROR:main:'dict_keys' object is not subscriptable]
Traceback (most recent call last):
  File "E:\Projects\MLOPS_MLFLOW-\main.py", line 26, in <module>
    data_ingestion.main()
  File "E:\Projects\MLOPS_MLFLOW-\src\MLProject\pipeline\stage_02_data_validation.py", line 16, in main
    data_validation.validate_all_columns()
  File "e:\projects\mlops_mlflow-\src\MLProject\components\data_validation.py", line 37, in validate_all_columns
    raise e
  File "e:\projects\mlops_mlflow-\src\MLProject\components\data_validation.py", line 20, in validate_all_columns
    if all_cols[0]==all_schema[0]:
TypeError: 'dict_keys' object is not subscriptable
[2023-10-26 01:03:07,456:INFO:utils:Note: NumExpr detected 16 cores but "NUMEXPR_MAX_THREADS" not set, so enforcing safe limit of 8.]
[2023-10-26 01:03:07,457:INFO:utils:NumExpr defaulting to 8 threads.]
[2023-10-26 01:03:08,923:INFO:main:>>>>>> stage Data Ingestion stage started <<<<<<]
[2023-10-26 01:03:08,926:INFO:common:yaml file: config\config.yaml loaded successfully]
[2023-10-26 01:03:08,927:INFO:common:yaml file: params.yaml loaded successfully]
[2023-10-26 01:03:08,929:INFO:common:yaml file: schema.yaml loaded successfully]
[2023-10-26 01:03:08,929:INFO:common:created directory at: artifacts]
[2023-10-26 01:03:08,929:INFO:common:created directory at: artifacts/data_ingestion]
[2023-10-26 01:03:08,929:INFO:data_ingestion:File already exists of size: ~ 94 KB]
[2023-10-26 01:03:08,933:INFO:main:>>>>>> stage Data Ingestion stage completed <<<<<<

x==========x]
[2023-10-26 01:03:08,933:INFO:main:>>>>>> stage Data Validation stage started <<<<<<]
[2023-10-26 01:03:08,935:INFO:common:yaml file: config\config.yaml loaded successfully]
[2023-10-26 01:03:08,936:INFO:common:yaml file: params.yaml loaded successfully]
[2023-10-26 01:03:08,937:INFO:common:yaml file: schema.yaml loaded successfully]
[2023-10-26 01:03:08,938:INFO:common:created directory at: artifacts]
[2023-10-26 01:03:08,938:INFO:common:created directory at: artifacts/data_validation]
[2023-10-26 01:03:08,945:ERROR:main:'dict_keys' object has no attribute 'keys']
Traceback (most recent call last):
  File "E:\Projects\MLOPS_MLFLOW-\main.py", line 26, in <module>
    data_ingestion.main()
  File "E:\Projects\MLOPS_MLFLOW-\src\MLProject\pipeline\stage_02_data_validation.py", line 16, in main
    data_validation.validate_all_columns()
  File "e:\projects\mlops_mlflow-\src\MLProject\components\data_validation.py", line 37, in validate_all_columns
    raise e
  File "e:\projects\mlops_mlflow-\src\MLProject\components\data_validation.py", line 20, in validate_all_columns
    if all_cols[0]==all_schema.keys()[0]:
AttributeError: 'dict_keys' object has no attribute 'keys'
[2023-10-26 01:03:32,809:INFO:utils:Note: NumExpr detected 16 cores but "NUMEXPR_MAX_THREADS" not set, so enforcing safe limit of 8.]
[2023-10-26 01:03:32,809:INFO:utils:NumExpr defaulting to 8 threads.]
[2023-10-26 01:03:34,284:INFO:main:>>>>>> stage Data Ingestion stage started <<<<<<]
[2023-10-26 01:03:34,287:INFO:common:yaml file: config\config.yaml loaded successfully]
[2023-10-26 01:03:34,288:INFO:common:yaml file: params.yaml loaded successfully]
[2023-10-26 01:03:34,289:INFO:common:yaml file: schema.yaml loaded successfully]
[2023-10-26 01:03:34,289:INFO:common:created directory at: artifacts]
[2023-10-26 01:03:34,290:INFO:common:created directory at: artifacts/data_ingestion]
[2023-10-26 01:03:34,290:INFO:data_ingestion:File already exists of size: ~ 94 KB]
[2023-10-26 01:03:34,293:INFO:main:>>>>>> stage Data Ingestion stage completed <<<<<<

x==========x]
[2023-10-26 01:03:34,294:INFO:main:>>>>>> stage Data Validation stage started <<<<<<]
[2023-10-26 01:03:34,296:INFO:common:yaml file: config\config.yaml loaded successfully]
[2023-10-26 01:03:34,296:INFO:common:yaml file: params.yaml loaded successfully]
[2023-10-26 01:03:34,298:INFO:common:yaml file: schema.yaml loaded successfully]
[2023-10-26 01:03:34,299:INFO:common:created directory at: artifacts]
[2023-10-26 01:03:34,299:INFO:common:created directory at: artifacts/data_validation]
[2023-10-26 01:03:34,306:ERROR:main:'dict_keys' object is not subscriptable]
Traceback (most recent call last):
  File "E:\Projects\MLOPS_MLFLOW-\main.py", line 26, in <module>
    data_ingestion.main()
  File "E:\Projects\MLOPS_MLFLOW-\src\MLProject\pipeline\stage_02_data_validation.py", line 16, in main
    data_validation.validate_all_columns()
  File "e:\projects\mlops_mlflow-\src\MLProject\components\data_validation.py", line 37, in validate_all_columns
    raise e
  File "e:\projects\mlops_mlflow-\src\MLProject\components\data_validation.py", line 20, in validate_all_columns
    if all_cols[0]==all_schema[0]:
TypeError: 'dict_keys' object is not subscriptable
[2023-10-26 01:04:01,173:INFO:utils:Note: NumExpr detected 16 cores but "NUMEXPR_MAX_THREADS" not set, so enforcing safe limit of 8.]
[2023-10-26 01:04:01,173:INFO:utils:NumExpr defaulting to 8 threads.]
[2023-10-26 01:04:02,641:INFO:main:>>>>>> stage Data Ingestion stage started <<<<<<]
[2023-10-26 01:04:02,643:INFO:common:yaml file: config\config.yaml loaded successfully]
[2023-10-26 01:04:02,644:INFO:common:yaml file: params.yaml loaded successfully]
[2023-10-26 01:04:02,645:INFO:common:yaml file: schema.yaml loaded successfully]
[2023-10-26 01:04:02,646:INFO:common:created directory at: artifacts]
[2023-10-26 01:04:02,646:INFO:common:created directory at: artifacts/data_ingestion]
[2023-10-26 01:04:02,646:INFO:data_ingestion:File already exists of size: ~ 94 KB]
[2023-10-26 01:04:02,650:INFO:main:>>>>>> stage Data Ingestion stage completed <<<<<<

x==========x]
[2023-10-26 01:04:02,650:INFO:main:>>>>>> stage Data Validation stage started <<<<<<]
[2023-10-26 01:04:02,652:INFO:common:yaml file: config\config.yaml loaded successfully]
[2023-10-26 01:04:02,653:INFO:common:yaml file: params.yaml loaded successfully]
[2023-10-26 01:04:02,654:INFO:common:yaml file: schema.yaml loaded successfully]
[2023-10-26 01:04:02,655:INFO:common:created directory at: artifacts]
[2023-10-26 01:04:02,655:INFO:common:created directory at: artifacts/data_validation]
[2023-10-26 01:04:02,663:ERROR:main:'dict_keys' object is not subscriptable]
Traceback (most recent call last):
  File "E:\Projects\MLOPS_MLFLOW-\main.py", line 26, in <module>
    data_ingestion.main()
  File "E:\Projects\MLOPS_MLFLOW-\src\MLProject\pipeline\stage_02_data_validation.py", line 16, in main
    data_validation.validate_all_columns()
  File "e:\projects\mlops_mlflow-\src\MLProject\components\data_validation.py", line 38, in validate_all_columns
    raise e
  File "e:\projects\mlops_mlflow-\src\MLProject\components\data_validation.py", line 21, in validate_all_columns
    if all_cols[0]==all_schema[0]:
TypeError: 'dict_keys' object is not subscriptable
[2023-10-26 01:05:36,666:INFO:utils:Note: NumExpr detected 16 cores but "NUMEXPR_MAX_THREADS" not set, so enforcing safe limit of 8.]
[2023-10-26 01:05:36,666:INFO:utils:NumExpr defaulting to 8 threads.]
[2023-10-26 01:05:38,135:INFO:main:>>>>>> stage Data Ingestion stage started <<<<<<]
[2023-10-26 01:05:38,137:INFO:common:yaml file: config\config.yaml loaded successfully]
[2023-10-26 01:05:38,139:INFO:common:yaml file: params.yaml loaded successfully]
[2023-10-26 01:05:38,140:INFO:common:yaml file: schema.yaml loaded successfully]
[2023-10-26 01:05:38,141:INFO:common:created directory at: artifacts]
[2023-10-26 01:05:38,141:INFO:common:created directory at: artifacts/data_ingestion]
[2023-10-26 01:05:38,141:INFO:data_ingestion:File already exists of size: ~ 94 KB]
[2023-10-26 01:05:38,145:INFO:main:>>>>>> stage Data Ingestion stage completed <<<<<<

x==========x]
[2023-10-26 01:05:38,145:INFO:main:>>>>>> stage Data Validation stage started <<<<<<]
[2023-10-26 01:05:38,147:INFO:common:yaml file: config\config.yaml loaded successfully]
[2023-10-26 01:05:38,147:INFO:common:yaml file: params.yaml loaded successfully]
[2023-10-26 01:05:38,149:INFO:common:yaml file: schema.yaml loaded successfully]
[2023-10-26 01:05:38,149:INFO:common:created directory at: artifacts]
[2023-10-26 01:05:38,149:INFO:common:created directory at: artifacts/data_validation]
[2023-10-26 01:05:38,158:ERROR:main:'dict_keys' object is not subscriptable]
Traceback (most recent call last):
  File "E:\Projects\MLOPS_MLFLOW-\main.py", line 26, in <module>
    data_ingestion.main()
  File "E:\Projects\MLOPS_MLFLOW-\src\MLProject\pipeline\stage_02_data_validation.py", line 16, in main
    data_validation.validate_all_columns()
  File "e:\projects\mlops_mlflow-\src\MLProject\components\data_validation.py", line 37, in validate_all_columns
    raise e
  File "e:\projects\mlops_mlflow-\src\MLProject\components\data_validation.py", line 20, in validate_all_columns
    print("22232--- ",all_schema[0])
TypeError: 'dict_keys' object is not subscriptable
[2023-10-26 01:06:02,871:INFO:utils:Note: NumExpr detected 16 cores but "NUMEXPR_MAX_THREADS" not set, so enforcing safe limit of 8.]
[2023-10-26 01:06:02,871:INFO:utils:NumExpr defaulting to 8 threads.]
[2023-10-26 01:06:04,333:INFO:main:>>>>>> stage Data Ingestion stage started <<<<<<]
[2023-10-26 01:06:04,335:INFO:common:yaml file: config\config.yaml loaded successfully]
[2023-10-26 01:06:04,336:INFO:common:yaml file: params.yaml loaded successfully]
[2023-10-26 01:06:04,337:INFO:common:yaml file: schema.yaml loaded successfully]
[2023-10-26 01:06:04,337:INFO:common:created directory at: artifacts]
[2023-10-26 01:06:04,338:INFO:common:created directory at: artifacts/data_ingestion]
[2023-10-26 01:06:04,338:INFO:data_ingestion:File already exists of size: ~ 94 KB]
[2023-10-26 01:06:04,341:INFO:main:>>>>>> stage Data Ingestion stage completed <<<<<<

x==========x]
[2023-10-26 01:06:04,342:INFO:main:>>>>>> stage Data Validation stage started <<<<<<]
[2023-10-26 01:06:04,344:INFO:common:yaml file: config\config.yaml loaded successfully]
[2023-10-26 01:06:04,344:INFO:common:yaml file: params.yaml loaded successfully]
[2023-10-26 01:06:04,346:INFO:common:yaml file: schema.yaml loaded successfully]
[2023-10-26 01:06:04,346:INFO:common:created directory at: artifacts]
[2023-10-26 01:06:04,347:INFO:common:created directory at: artifacts/data_validation]
[2023-10-26 01:06:04,354:INFO:main:>>>>>> stage Data Validation stage completed <<<<<<

x==========x]
[2023-10-26 01:06:04,354:INFO:main:>>>>>> stage Data Transformation stage started <<<<<<]
[2023-10-26 01:06:04,355:INFO:main:>>>>>> stage Data Transformation stage completed <<<<<<

x==========x]
[2023-10-26 01:06:04,355:INFO:main:>>>>>> stage Model Trainer stage started <<<<<<]
[2023-10-26 01:06:04,358:INFO:common:yaml file: config\config.yaml loaded successfully]
[2023-10-26 01:06:04,358:INFO:common:yaml file: params.yaml loaded successfully]
[2023-10-26 01:06:04,360:INFO:common:yaml file: schema.yaml loaded successfully]
[2023-10-26 01:06:04,360:INFO:common:created directory at: artifacts]
[2023-10-26 01:06:04,360:INFO:common:created directory at: artifacts/model_trainer]
[2023-10-26 01:06:04,361:ERROR:main:[Errno 2] No such file or directory: 'artifacts/data_transformation/train.csv']
Traceback (most recent call last):
  File "E:\Projects\MLOPS_MLFLOW-\main.py", line 51, in <module>
    data_ingestion.main()
  File "E:\Projects\MLOPS_MLFLOW-\src\MLProject\pipeline\stage_04_model_trainer.py", line 17, in main
    model_trainer_config.train()
  File "e:\projects\mlops_mlflow-\src\MLProject\components\model_trainer.py", line 16, in train
    train_data = pd.read_csv(self.config.train_data_path)
  File "C:\Users\madhu\AppData\Roaming\Python\Python39\site-packages\pandas\io\parsers\readers.py", line 948, in read_csv
    return _read(filepath_or_buffer, kwds)
  File "C:\Users\madhu\AppData\Roaming\Python\Python39\site-packages\pandas\io\parsers\readers.py", line 611, in _read
    parser = TextFileReader(filepath_or_buffer, **kwds)
  File "C:\Users\madhu\AppData\Roaming\Python\Python39\site-packages\pandas\io\parsers\readers.py", line 1448, in __init__
    self._engine = self._make_engine(f, self.engine)
  File "C:\Users\madhu\AppData\Roaming\Python\Python39\site-packages\pandas\io\parsers\readers.py", line 1705, in _make_engine
    self.handles = get_handle(
  File "C:\Users\madhu\AppData\Roaming\Python\Python39\site-packages\pandas\io\common.py", line 863, in get_handle
    handle = open(
FileNotFoundError: [Errno 2] No such file or directory: 'artifacts/data_transformation/train.csv'
[2023-10-26 01:07:06,310:INFO:utils:Note: NumExpr detected 16 cores but "NUMEXPR_MAX_THREADS" not set, so enforcing safe limit of 8.]
[2023-10-26 01:07:06,310:INFO:utils:NumExpr defaulting to 8 threads.]
[2023-10-26 01:07:07,795:INFO:main:>>>>>> stage Data Ingestion stage started <<<<<<]
[2023-10-26 01:07:07,797:INFO:common:yaml file: config\config.yaml loaded successfully]
[2023-10-26 01:07:07,798:INFO:common:yaml file: params.yaml loaded successfully]
[2023-10-26 01:07:07,800:INFO:common:yaml file: schema.yaml loaded successfully]
[2023-10-26 01:07:07,800:INFO:common:created directory at: artifacts]
[2023-10-26 01:07:07,800:INFO:common:created directory at: artifacts/data_ingestion]
[2023-10-26 01:07:07,801:INFO:data_ingestion:File already exists of size: ~ 94 KB]
[2023-10-26 01:07:07,804:INFO:main:>>>>>> stage Data Ingestion stage completed <<<<<<

x==========x]
[2023-10-26 01:07:07,804:INFO:main:>>>>>> stage Data Validation stage started <<<<<<]
[2023-10-26 01:07:07,806:INFO:common:yaml file: config\config.yaml loaded successfully]
[2023-10-26 01:07:07,807:INFO:common:yaml file: params.yaml loaded successfully]
[2023-10-26 01:07:07,808:INFO:common:yaml file: schema.yaml loaded successfully]
[2023-10-26 01:07:07,809:INFO:common:created directory at: artifacts]
[2023-10-26 01:07:07,809:INFO:common:created directory at: artifacts/data_validation]
[2023-10-26 01:07:07,817:INFO:main:>>>>>> stage Data Validation stage completed <<<<<<

x==========x]
[2023-10-26 01:07:07,817:INFO:main:>>>>>> stage Data Transformation stage started <<<<<<]
[2023-10-26 01:07:07,818:INFO:main:>>>>>> stage Data Transformation stage completed <<<<<<

x==========x]
[2023-10-26 01:07:07,819:INFO:main:>>>>>> stage Model Trainer stage started <<<<<<]
[2023-10-26 01:07:07,821:INFO:common:yaml file: config\config.yaml loaded successfully]
[2023-10-26 01:07:07,822:INFO:common:yaml file: params.yaml loaded successfully]
[2023-10-26 01:07:07,823:INFO:common:yaml file: schema.yaml loaded successfully]
[2023-10-26 01:07:07,823:INFO:common:created directory at: artifacts]
[2023-10-26 01:07:07,824:INFO:common:created directory at: artifacts/model_trainer]
[2023-10-26 01:07:07,824:ERROR:main:[Errno 2] No such file or directory: 'artifacts/data_transformation/train.csv']
Traceback (most recent call last):
  File "E:\Projects\MLOPS_MLFLOW-\main.py", line 51, in <module>
    data_ingestion.main()
  File "E:\Projects\MLOPS_MLFLOW-\src\MLProject\pipeline\stage_04_model_trainer.py", line 17, in main
    model_trainer_config.train()
  File "e:\projects\mlops_mlflow-\src\MLProject\components\model_trainer.py", line 16, in train
    train_data = pd.read_csv(self.config.train_data_path)
  File "C:\Users\madhu\AppData\Roaming\Python\Python39\site-packages\pandas\io\parsers\readers.py", line 948, in read_csv
    return _read(filepath_or_buffer, kwds)
  File "C:\Users\madhu\AppData\Roaming\Python\Python39\site-packages\pandas\io\parsers\readers.py", line 611, in _read
    parser = TextFileReader(filepath_or_buffer, **kwds)
  File "C:\Users\madhu\AppData\Roaming\Python\Python39\site-packages\pandas\io\parsers\readers.py", line 1448, in __init__
    self._engine = self._make_engine(f, self.engine)
  File "C:\Users\madhu\AppData\Roaming\Python\Python39\site-packages\pandas\io\parsers\readers.py", line 1705, in _make_engine
    self.handles = get_handle(
  File "C:\Users\madhu\AppData\Roaming\Python\Python39\site-packages\pandas\io\common.py", line 863, in get_handle
    handle = open(
FileNotFoundError: [Errno 2] No such file or directory: 'artifacts/data_transformation/train.csv'
[2023-10-26 01:07:33,895:INFO:utils:Note: NumExpr detected 16 cores but "NUMEXPR_MAX_THREADS" not set, so enforcing safe limit of 8.]
[2023-10-26 01:07:33,895:INFO:utils:NumExpr defaulting to 8 threads.]
[2023-10-26 01:07:35,370:INFO:main:>>>>>> stage Data Ingestion stage started <<<<<<]
[2023-10-26 01:07:35,373:INFO:common:yaml file: config\config.yaml loaded successfully]
[2023-10-26 01:07:35,374:INFO:common:yaml file: params.yaml loaded successfully]
[2023-10-26 01:07:35,375:INFO:common:yaml file: schema.yaml loaded successfully]
[2023-10-26 01:07:35,375:INFO:common:created directory at: artifacts]
[2023-10-26 01:07:35,376:INFO:common:created directory at: artifacts/data_ingestion]
[2023-10-26 01:07:35,376:INFO:data_ingestion:File already exists of size: ~ 94 KB]
[2023-10-26 01:07:35,379:INFO:main:>>>>>> stage Data Ingestion stage completed <<<<<<

x==========x]
[2023-10-26 01:07:35,379:INFO:main:>>>>>> stage Data Validation stage started <<<<<<]
[2023-10-26 01:07:35,382:INFO:common:yaml file: config\config.yaml loaded successfully]
[2023-10-26 01:07:35,382:INFO:common:yaml file: params.yaml loaded successfully]
[2023-10-26 01:07:35,384:INFO:common:yaml file: schema.yaml loaded successfully]
[2023-10-26 01:07:35,384:INFO:common:created directory at: artifacts]
[2023-10-26 01:07:35,384:INFO:common:created directory at: artifacts/data_validation]
[2023-10-26 01:07:35,392:INFO:main:>>>>>> stage Data Validation stage completed <<<<<<

x==========x]
[2023-10-26 01:07:35,392:INFO:main:>>>>>> stage Data Transformation stage started <<<<<<]
[2023-10-26 01:07:35,393:INFO:main:>>>>>> stage Data Transformation stage completed <<<<<<

x==========x]
[2023-10-26 01:07:35,393:INFO:main:>>>>>> stage Model Trainer stage started <<<<<<]
[2023-10-26 01:07:35,396:INFO:common:yaml file: config\config.yaml loaded successfully]
[2023-10-26 01:07:35,396:INFO:common:yaml file: params.yaml loaded successfully]
[2023-10-26 01:07:35,398:INFO:common:yaml file: schema.yaml loaded successfully]
[2023-10-26 01:07:35,398:INFO:common:created directory at: artifacts]
[2023-10-26 01:07:35,398:INFO:common:created directory at: artifacts/model_trainer]
[2023-10-26 01:07:35,399:ERROR:main:[Errno 2] No such file or directory: 'artifacts/data_transformation/train.csv']
Traceback (most recent call last):
  File "E:\Projects\MLOPS_MLFLOW-\main.py", line 51, in <module>
    data_ingestion.main()
  File "E:\Projects\MLOPS_MLFLOW-\src\MLProject\pipeline\stage_04_model_trainer.py", line 17, in main
    model_trainer_config.train()
  File "e:\projects\mlops_mlflow-\src\MLProject\components\model_trainer.py", line 16, in train
    train_data = pd.read_csv(self.config.train_data_path)
  File "C:\Users\madhu\AppData\Roaming\Python\Python39\site-packages\pandas\io\parsers\readers.py", line 948, in read_csv
    return _read(filepath_or_buffer, kwds)
  File "C:\Users\madhu\AppData\Roaming\Python\Python39\site-packages\pandas\io\parsers\readers.py", line 611, in _read
    parser = TextFileReader(filepath_or_buffer, **kwds)
  File "C:\Users\madhu\AppData\Roaming\Python\Python39\site-packages\pandas\io\parsers\readers.py", line 1448, in __init__
    self._engine = self._make_engine(f, self.engine)
  File "C:\Users\madhu\AppData\Roaming\Python\Python39\site-packages\pandas\io\parsers\readers.py", line 1705, in _make_engine
    self.handles = get_handle(
  File "C:\Users\madhu\AppData\Roaming\Python\Python39\site-packages\pandas\io\common.py", line 863, in get_handle
    handle = open(
FileNotFoundError: [Errno 2] No such file or directory: 'artifacts/data_transformation/train.csv'
[2023-10-26 01:08:43,068:INFO:utils:Note: NumExpr detected 16 cores but "NUMEXPR_MAX_THREADS" not set, so enforcing safe limit of 8.]
[2023-10-26 01:08:43,068:INFO:utils:NumExpr defaulting to 8 threads.]
[2023-10-26 01:08:44,533:INFO:main:>>>>>> stage Data Ingestion stage started <<<<<<]
[2023-10-26 01:08:44,536:INFO:common:yaml file: config\config.yaml loaded successfully]
[2023-10-26 01:08:44,537:INFO:common:yaml file: params.yaml loaded successfully]
[2023-10-26 01:08:44,538:INFO:common:yaml file: schema.yaml loaded successfully]
[2023-10-26 01:08:44,538:INFO:common:created directory at: artifacts]
[2023-10-26 01:08:44,539:INFO:common:created directory at: artifacts/data_ingestion]
[2023-10-26 01:08:44,539:INFO:data_ingestion:File already exists of size: ~ 94 KB]
[2023-10-26 01:08:44,543:INFO:main:>>>>>> stage Data Ingestion stage completed <<<<<<

x==========x]
[2023-10-26 01:08:44,543:INFO:main:>>>>>> stage Data Validation stage started <<<<<<]
[2023-10-26 01:08:44,545:INFO:common:yaml file: config\config.yaml loaded successfully]
[2023-10-26 01:08:44,546:INFO:common:yaml file: params.yaml loaded successfully]
[2023-10-26 01:08:44,547:INFO:common:yaml file: schema.yaml loaded successfully]
[2023-10-26 01:08:44,548:INFO:common:created directory at: artifacts]
[2023-10-26 01:08:44,548:INFO:common:created directory at: artifacts/data_validation]
[2023-10-26 01:08:44,556:INFO:main:>>>>>> stage Data Validation stage completed <<<<<<

x==========x]
[2023-10-26 01:08:44,556:INFO:main:>>>>>> stage Data Transformation stage started <<<<<<]
[2023-10-26 01:08:44,557:INFO:main:>>>>>> stage Data Transformation stage completed <<<<<<

x==========x]
[2023-10-26 01:08:44,557:INFO:main:>>>>>> stage Model Trainer stage started <<<<<<]
[2023-10-26 01:08:44,559:INFO:common:yaml file: config\config.yaml loaded successfully]
[2023-10-26 01:08:44,560:INFO:common:yaml file: params.yaml loaded successfully]
[2023-10-26 01:08:44,561:INFO:common:yaml file: schema.yaml loaded successfully]
[2023-10-26 01:08:44,562:INFO:common:created directory at: artifacts]
[2023-10-26 01:08:44,562:INFO:common:created directory at: artifacts/model_trainer]
[2023-10-26 01:08:44,562:ERROR:main:[Errno 2] No such file or directory: 'artifacts/data_transformation/train.csv']
Traceback (most recent call last):
  File "E:\Projects\MLOPS_MLFLOW-\main.py", line 51, in <module>
    data_ingestion.main()
  File "E:\Projects\MLOPS_MLFLOW-\src\MLProject\pipeline\stage_04_model_trainer.py", line 17, in main
    model_trainer_config.train()
  File "e:\projects\mlops_mlflow-\src\MLProject\components\model_trainer.py", line 16, in train
    train_data = pd.read_csv(self.config.train_data_path)
  File "C:\Users\madhu\AppData\Roaming\Python\Python39\site-packages\pandas\io\parsers\readers.py", line 948, in read_csv
    return _read(filepath_or_buffer, kwds)
  File "C:\Users\madhu\AppData\Roaming\Python\Python39\site-packages\pandas\io\parsers\readers.py", line 611, in _read
    parser = TextFileReader(filepath_or_buffer, **kwds)
  File "C:\Users\madhu\AppData\Roaming\Python\Python39\site-packages\pandas\io\parsers\readers.py", line 1448, in __init__
    self._engine = self._make_engine(f, self.engine)
  File "C:\Users\madhu\AppData\Roaming\Python\Python39\site-packages\pandas\io\parsers\readers.py", line 1705, in _make_engine
    self.handles = get_handle(
  File "C:\Users\madhu\AppData\Roaming\Python\Python39\site-packages\pandas\io\common.py", line 863, in get_handle
    handle = open(
FileNotFoundError: [Errno 2] No such file or directory: 'artifacts/data_transformation/train.csv'
[2023-10-26 01:13:00,725:INFO:utils:Note: NumExpr detected 16 cores but "NUMEXPR_MAX_THREADS" not set, so enforcing safe limit of 8.]
[2023-10-26 01:13:00,726:INFO:utils:NumExpr defaulting to 8 threads.]
[2023-10-26 01:13:02,228:INFO:main:>>>>>> stage Data Ingestion stage started <<<<<<]
[2023-10-26 01:13:02,230:INFO:common:yaml file: config\config.yaml loaded successfully]
[2023-10-26 01:13:02,231:INFO:common:yaml file: params.yaml loaded successfully]
[2023-10-26 01:13:02,232:INFO:common:yaml file: schema.yaml loaded successfully]
[2023-10-26 01:13:02,232:INFO:common:created directory at: artifacts]
[2023-10-26 01:13:02,233:INFO:common:created directory at: artifacts/data_ingestion]
[2023-10-26 01:13:02,233:INFO:data_ingestion:File already exists of size: ~ 94 KB]
[2023-10-26 01:13:02,237:INFO:main:>>>>>> stage Data Ingestion stage completed <<<<<<

x==========x]
[2023-10-26 01:13:02,237:INFO:main:>>>>>> stage Data Validation stage started <<<<<<]
[2023-10-26 01:13:02,239:INFO:common:yaml file: config\config.yaml loaded successfully]
[2023-10-26 01:13:02,240:INFO:common:yaml file: params.yaml loaded successfully]
[2023-10-26 01:13:02,241:INFO:common:yaml file: schema.yaml loaded successfully]
[2023-10-26 01:13:02,241:INFO:common:created directory at: artifacts]
[2023-10-26 01:13:02,242:INFO:common:created directory at: artifacts/data_validation]
[2023-10-26 01:13:02,250:INFO:main:>>>>>> stage Data Validation stage completed <<<<<<

x==========x]
[2023-10-26 01:13:02,250:INFO:main:>>>>>> stage Data Transformation stage started <<<<<<]
[2023-10-26 01:13:02,251:INFO:main:>>>>>> stage Data Transformation stage completed <<<<<<

x==========x]
[2023-10-26 01:13:02,251:INFO:main:>>>>>> stage Model Trainer stage started <<<<<<]
[2023-10-26 01:13:02,253:INFO:common:yaml file: config\config.yaml loaded successfully]
[2023-10-26 01:13:02,254:INFO:common:yaml file: params.yaml loaded successfully]
[2023-10-26 01:13:02,255:INFO:common:yaml file: schema.yaml loaded successfully]
[2023-10-26 01:13:02,255:INFO:common:created directory at: artifacts]
[2023-10-26 01:13:02,256:INFO:common:created directory at: artifacts/model_trainer]
[2023-10-26 01:13:02,256:ERROR:main:[Errno 2] No such file or directory: 'artifacts/data_transformation/train.csv']
Traceback (most recent call last):
  File "E:\Projects\MLOPS_MLFLOW-\main.py", line 51, in <module>
    data_ingestion.main()
  File "E:\Projects\MLOPS_MLFLOW-\src\MLProject\pipeline\stage_04_model_trainer.py", line 17, in main
    model_trainer_config.train()
  File "e:\projects\mlops_mlflow-\src\MLProject\components\model_trainer.py", line 16, in train
    train_data = pd.read_csv(self.config.train_data_path)
  File "C:\Users\madhu\AppData\Roaming\Python\Python39\site-packages\pandas\io\parsers\readers.py", line 948, in read_csv
    return _read(filepath_or_buffer, kwds)
  File "C:\Users\madhu\AppData\Roaming\Python\Python39\site-packages\pandas\io\parsers\readers.py", line 611, in _read
    parser = TextFileReader(filepath_or_buffer, **kwds)
  File "C:\Users\madhu\AppData\Roaming\Python\Python39\site-packages\pandas\io\parsers\readers.py", line 1448, in __init__
    self._engine = self._make_engine(f, self.engine)
  File "C:\Users\madhu\AppData\Roaming\Python\Python39\site-packages\pandas\io\parsers\readers.py", line 1705, in _make_engine
    self.handles = get_handle(
  File "C:\Users\madhu\AppData\Roaming\Python\Python39\site-packages\pandas\io\common.py", line 863, in get_handle
    handle = open(
FileNotFoundError: [Errno 2] No such file or directory: 'artifacts/data_transformation/train.csv'
[2023-10-26 01:15:02,354:INFO:utils:Note: NumExpr detected 16 cores but "NUMEXPR_MAX_THREADS" not set, so enforcing safe limit of 8.]
[2023-10-26 01:15:02,354:INFO:utils:NumExpr defaulting to 8 threads.]
[2023-10-26 01:15:03,823:INFO:main:>>>>>> stage Data Ingestion stage started <<<<<<]
[2023-10-26 01:15:03,825:INFO:common:yaml file: config\config.yaml loaded successfully]
[2023-10-26 01:15:03,826:INFO:common:yaml file: params.yaml loaded successfully]
[2023-10-26 01:15:03,828:INFO:common:yaml file: schema.yaml loaded successfully]
[2023-10-26 01:15:03,828:INFO:common:created directory at: artifacts]
[2023-10-26 01:15:03,828:INFO:common:created directory at: artifacts/data_ingestion]
[2023-10-26 01:15:03,828:INFO:data_ingestion:File already exists of size: ~ 94 KB]
[2023-10-26 01:15:03,832:INFO:main:>>>>>> stage Data Ingestion stage completed <<<<<<

x==========x]
[2023-10-26 01:15:03,832:INFO:main:>>>>>> stage Data Validation stage started <<<<<<]
[2023-10-26 01:15:03,834:INFO:common:yaml file: config\config.yaml loaded successfully]
[2023-10-26 01:15:03,835:INFO:common:yaml file: params.yaml loaded successfully]
[2023-10-26 01:15:03,836:INFO:common:yaml file: schema.yaml loaded successfully]
[2023-10-26 01:15:03,837:INFO:common:created directory at: artifacts]
[2023-10-26 01:15:03,837:INFO:common:created directory at: artifacts/data_validation]
[2023-10-26 01:15:03,846:INFO:main:>>>>>> stage Data Validation stage completed <<<<<<

x==========x]
[2023-10-26 01:15:03,846:INFO:main:>>>>>> stage Data Transformation stage started <<<<<<]
[2023-10-26 01:15:03,847:INFO:main:>>>>>> stage Data Transformation stage completed <<<<<<

x==========x]
[2023-10-26 01:15:03,847:INFO:main:>>>>>> stage Model Trainer stage started <<<<<<]
[2023-10-26 01:15:03,849:INFO:common:yaml file: config\config.yaml loaded successfully]
[2023-10-26 01:15:03,850:INFO:common:yaml file: params.yaml loaded successfully]
[2023-10-26 01:15:03,852:INFO:common:yaml file: schema.yaml loaded successfully]
[2023-10-26 01:15:03,852:INFO:common:created directory at: artifacts]
[2023-10-26 01:15:03,852:INFO:common:created directory at: artifacts/model_trainer]
[2023-10-26 01:15:03,853:ERROR:main:[Errno 2] No such file or directory: 'artifacts/data_transformation/train.csv']
Traceback (most recent call last):
  File "E:\Projects\MLOPS_MLFLOW-\main.py", line 51, in <module>
    data_ingestion.main()
  File "E:\Projects\MLOPS_MLFLOW-\src\MLProject\pipeline\stage_04_model_trainer.py", line 17, in main
    model_trainer_config.train()
  File "e:\projects\mlops_mlflow-\src\MLProject\components\model_trainer.py", line 16, in train
    train_data = pd.read_csv(self.config.train_data_path)
  File "C:\Users\madhu\AppData\Roaming\Python\Python39\site-packages\pandas\io\parsers\readers.py", line 948, in read_csv
    return _read(filepath_or_buffer, kwds)
  File "C:\Users\madhu\AppData\Roaming\Python\Python39\site-packages\pandas\io\parsers\readers.py", line 611, in _read
    parser = TextFileReader(filepath_or_buffer, **kwds)
  File "C:\Users\madhu\AppData\Roaming\Python\Python39\site-packages\pandas\io\parsers\readers.py", line 1448, in __init__
    self._engine = self._make_engine(f, self.engine)
  File "C:\Users\madhu\AppData\Roaming\Python\Python39\site-packages\pandas\io\parsers\readers.py", line 1705, in _make_engine
    self.handles = get_handle(
  File "C:\Users\madhu\AppData\Roaming\Python\Python39\site-packages\pandas\io\common.py", line 863, in get_handle
    handle = open(
FileNotFoundError: [Errno 2] No such file or directory: 'artifacts/data_transformation/train.csv'
[2023-10-26 01:19:34,608:INFO:utils:Note: NumExpr detected 16 cores but "NUMEXPR_MAX_THREADS" not set, so enforcing safe limit of 8.]
[2023-10-26 01:19:34,608:INFO:utils:NumExpr defaulting to 8 threads.]
[2023-10-26 01:19:36,113:INFO:main:>>>>>> stage Data Ingestion stage started <<<<<<]
[2023-10-26 01:19:36,116:INFO:common:yaml file: config\config.yaml loaded successfully]
[2023-10-26 01:19:36,116:INFO:common:yaml file: params.yaml loaded successfully]
[2023-10-26 01:19:36,118:INFO:common:yaml file: schema.yaml loaded successfully]
[2023-10-26 01:19:36,118:INFO:common:created directory at: artifacts]
[2023-10-26 01:19:36,119:INFO:common:created directory at: artifacts/data_ingestion]
[2023-10-26 01:19:40,778:INFO:data_ingestion:artifacts/data_ingestion/data.zip download! with following info: 
Content-Type: application/x-zip-compressed
Last-Modified: Wed, 07 Oct 2009 14:56:35 GMT
Accept-Ranges: bytes
ETag: "8013395d5e47ca1:0"
Server: Microsoft-IIS/10.0
X-Powered-By: ASP.NET
Date: Wed, 25 Oct 2023 19:49:41 GMT
Connection: close
Content-Length: 96005

]
[2023-10-26 01:19:40,805:INFO:main:>>>>>> stage Data Ingestion stage completed <<<<<<

x==========x]
[2023-10-26 01:19:40,806:INFO:main:>>>>>> stage Data Validation stage started <<<<<<]
[2023-10-26 01:19:40,811:INFO:common:yaml file: config\config.yaml loaded successfully]
[2023-10-26 01:19:40,813:INFO:common:yaml file: params.yaml loaded successfully]
[2023-10-26 01:19:40,817:INFO:common:yaml file: schema.yaml loaded successfully]
[2023-10-26 01:19:40,817:INFO:common:created directory at: artifacts]
[2023-10-26 01:19:40,818:INFO:common:created directory at: artifacts/data_validation]
[2023-10-26 01:19:40,830:INFO:main:>>>>>> stage Data Validation stage completed <<<<<<

x==========x]
[2023-10-26 01:19:40,831:INFO:main:>>>>>> stage Data Transformation stage started <<<<<<]
[2023-10-26 01:19:40,832:INFO:main:>>>>>> stage Data Transformation stage completed <<<<<<

x==========x]
[2023-10-26 01:19:40,832:INFO:main:>>>>>> stage Model Trainer stage started <<<<<<]
[2023-10-26 01:19:40,836:INFO:common:yaml file: config\config.yaml loaded successfully]
[2023-10-26 01:19:40,837:INFO:common:yaml file: params.yaml loaded successfully]
[2023-10-26 01:19:40,839:INFO:common:yaml file: schema.yaml loaded successfully]
[2023-10-26 01:19:40,840:INFO:common:created directory at: artifacts]
[2023-10-26 01:19:40,840:INFO:common:created directory at: artifacts/model_trainer]
[2023-10-26 01:19:40,841:ERROR:main:[Errno 2] No such file or directory: 'artifacts/data_transformation/train.csv']
Traceback (most recent call last):
  File "E:\Projects\MLOPS_MLFLOW-\main.py", line 51, in <module>
    data_ingestion.main()
  File "E:\Projects\MLOPS_MLFLOW-\src\MLProject\pipeline\stage_04_model_trainer.py", line 17, in main
    model_trainer_config.train()
  File "e:\projects\mlops_mlflow-\src\MLProject\components\model_trainer.py", line 16, in train
    train_data = pd.read_csv(self.config.train_data_path)
  File "C:\Users\madhu\AppData\Roaming\Python\Python39\site-packages\pandas\io\parsers\readers.py", line 948, in read_csv
    return _read(filepath_or_buffer, kwds)
  File "C:\Users\madhu\AppData\Roaming\Python\Python39\site-packages\pandas\io\parsers\readers.py", line 611, in _read
    parser = TextFileReader(filepath_or_buffer, **kwds)
  File "C:\Users\madhu\AppData\Roaming\Python\Python39\site-packages\pandas\io\parsers\readers.py", line 1448, in __init__
    self._engine = self._make_engine(f, self.engine)
  File "C:\Users\madhu\AppData\Roaming\Python\Python39\site-packages\pandas\io\parsers\readers.py", line 1705, in _make_engine
    self.handles = get_handle(
  File "C:\Users\madhu\AppData\Roaming\Python\Python39\site-packages\pandas\io\common.py", line 863, in get_handle
    handle = open(
FileNotFoundError: [Errno 2] No such file or directory: 'artifacts/data_transformation/train.csv'
[2023-10-26 01:20:37,905:INFO:utils:Note: NumExpr detected 16 cores but "NUMEXPR_MAX_THREADS" not set, so enforcing safe limit of 8.]
[2023-10-26 01:20:37,906:INFO:utils:NumExpr defaulting to 8 threads.]
[2023-10-26 01:20:39,379:INFO:main:>>>>>> stage Data Ingestion stage started <<<<<<]
[2023-10-26 01:20:39,381:INFO:common:yaml file: config\config.yaml loaded successfully]
[2023-10-26 01:20:39,382:INFO:common:yaml file: params.yaml loaded successfully]
[2023-10-26 01:20:39,384:INFO:common:yaml file: schema.yaml loaded successfully]
[2023-10-26 01:20:39,384:INFO:common:created directory at: artifacts]
[2023-10-26 01:20:39,384:INFO:common:created directory at: artifacts/data_ingestion]
[2023-10-26 01:20:39,385:INFO:data_ingestion:File already exists of size: ~ 94 KB]
[2023-10-26 01:20:39,388:INFO:main:>>>>>> stage Data Ingestion stage completed <<<<<<

x==========x]
[2023-10-26 01:20:39,388:INFO:main:>>>>>> stage Data Validation stage started <<<<<<]
[2023-10-26 01:20:39,391:INFO:common:yaml file: config\config.yaml loaded successfully]
[2023-10-26 01:20:39,391:INFO:common:yaml file: params.yaml loaded successfully]
[2023-10-26 01:20:39,393:INFO:common:yaml file: schema.yaml loaded successfully]
[2023-10-26 01:20:39,393:INFO:common:created directory at: artifacts]
[2023-10-26 01:20:39,394:INFO:common:created directory at: artifacts/data_validation]
[2023-10-26 01:20:39,399:INFO:main:>>>>>> stage Data Validation stage completed <<<<<<

x==========x]
[2023-10-26 01:20:39,399:INFO:main:>>>>>> stage Data Transformation stage started <<<<<<]
[2023-10-26 01:20:39,405:INFO:common:yaml file: config\config.yaml loaded successfully]
[2023-10-26 01:20:39,406:INFO:common:yaml file: params.yaml loaded successfully]
[2023-10-26 01:20:39,407:INFO:common:yaml file: schema.yaml loaded successfully]
[2023-10-26 01:20:39,408:INFO:common:created directory at: artifacts]
[2023-10-26 01:20:39,408:INFO:common:created directory at: artifacts/data_transformation]
[2023-10-26 01:20:39,427:INFO:data_transformation:Splited data into training and test sets]
[2023-10-26 01:20:39,427:INFO:data_transformation:(1199, 12)]
[2023-10-26 01:20:39,428:INFO:data_transformation:(400, 12)]
[2023-10-26 01:20:39,428:INFO:main:>>>>>> stage Data Transformation stage completed <<<<<<

x==========x]
[2023-10-26 01:20:39,428:INFO:main:>>>>>> stage Model Trainer stage started <<<<<<]
[2023-10-26 01:20:39,431:INFO:common:yaml file: config\config.yaml loaded successfully]
[2023-10-26 01:20:39,431:INFO:common:yaml file: params.yaml loaded successfully]
[2023-10-26 01:20:39,433:INFO:common:yaml file: schema.yaml loaded successfully]
[2023-10-26 01:20:39,433:INFO:common:created directory at: artifacts]
[2023-10-26 01:20:39,433:INFO:common:created directory at: artifacts/model_trainer]
[2023-10-26 01:20:39,459:INFO:main:>>>>>> stage Model Trainer stage completed <<<<<<

x==========x]
[2023-10-26 01:20:39,460:INFO:main:>>>>>> stage Model evaluation stage started <<<<<<]
[2023-10-26 01:20:39,462:INFO:common:yaml file: config\config.yaml loaded successfully]
[2023-10-26 01:20:39,463:INFO:common:yaml file: params.yaml loaded successfully]
[2023-10-26 01:20:39,464:INFO:common:yaml file: schema.yaml loaded successfully]
[2023-10-26 01:20:39,464:INFO:common:created directory at: artifacts]
[2023-10-26 01:20:39,465:INFO:common:created directory at: artifacts/model_evaluation]
[2023-10-26 01:20:42,632:INFO:common:json file saved at: artifacts\model_evaluation\metrics.json]
[2023-10-26 01:21:27,875:INFO:main:>>>>>> stage Model evaluation stage completed <<<<<<

x==========x]
[2023-10-26 01:24:58,385:INFO:utils:Note: NumExpr detected 16 cores but "NUMEXPR_MAX_THREADS" not set, so enforcing safe limit of 8.]
[2023-10-26 01:24:58,386:INFO:utils:NumExpr defaulting to 8 threads.]
[2023-10-26 01:24:59,856:INFO:main:>>>>>> stage Data Ingestion stage started <<<<<<]
[2023-10-26 01:24:59,859:INFO:common:yaml file: config\config.yaml loaded successfully]
[2023-10-26 01:24:59,860:INFO:common:yaml file: params.yaml loaded successfully]
[2023-10-26 01:24:59,861:INFO:common:yaml file: schema.yaml loaded successfully]
[2023-10-26 01:24:59,861:INFO:common:created directory at: artifacts]
[2023-10-26 01:24:59,862:INFO:common:created directory at: artifacts/data_ingestion]
[2023-10-26 01:24:59,862:INFO:data_ingestion:File already exists of size: ~ 94 KB]
[2023-10-26 01:24:59,865:INFO:main:>>>>>> stage Data Ingestion stage completed <<<<<<

x==========x]
[2023-10-26 01:24:59,865:INFO:main:>>>>>> stage Data Validation stage started <<<<<<]
[2023-10-26 01:24:59,867:INFO:common:yaml file: config\config.yaml loaded successfully]
[2023-10-26 01:24:59,868:INFO:common:yaml file: params.yaml loaded successfully]
[2023-10-26 01:24:59,869:INFO:common:yaml file: schema.yaml loaded successfully]
[2023-10-26 01:24:59,870:INFO:common:created directory at: artifacts]
[2023-10-26 01:24:59,870:INFO:common:created directory at: artifacts/data_validation]
[2023-10-26 01:24:59,875:INFO:main:>>>>>> stage Data Validation stage completed <<<<<<

x==========x]
[2023-10-26 01:24:59,875:INFO:main:>>>>>> stage Data Transformation stage started <<<<<<]
[2023-10-26 01:24:59,878:INFO:common:yaml file: config\config.yaml loaded successfully]
[2023-10-26 01:24:59,879:INFO:common:yaml file: params.yaml loaded successfully]
[2023-10-26 01:24:59,881:INFO:common:yaml file: schema.yaml loaded successfully]
[2023-10-26 01:24:59,881:INFO:common:created directory at: artifacts]
[2023-10-26 01:24:59,882:INFO:common:created directory at: artifacts/data_transformation]
[2023-10-26 01:24:59,894:INFO:data_transformation:Splited data into training and test sets]
[2023-10-26 01:24:59,895:INFO:data_transformation:(1199, 12)]
[2023-10-26 01:24:59,895:INFO:data_transformation:(400, 12)]
[2023-10-26 01:24:59,895:INFO:main:>>>>>> stage Data Transformation stage completed <<<<<<

x==========x]
[2023-10-26 01:24:59,896:INFO:main:>>>>>> stage Model Trainer stage started <<<<<<]
[2023-10-26 01:24:59,898:INFO:common:yaml file: config\config.yaml loaded successfully]
[2023-10-26 01:24:59,899:INFO:common:yaml file: params.yaml loaded successfully]
[2023-10-26 01:24:59,900:INFO:common:yaml file: schema.yaml loaded successfully]
[2023-10-26 01:24:59,900:INFO:common:created directory at: artifacts]
[2023-10-26 01:24:59,900:INFO:common:created directory at: artifacts/model_trainer]
[2023-10-26 01:24:59,921:INFO:main:>>>>>> stage Model Trainer stage completed <<<<<<

x==========x]
[2023-10-26 01:24:59,921:INFO:main:>>>>>> stage Model evaluation stage started <<<<<<]
[2023-10-26 01:24:59,924:INFO:common:yaml file: config\config.yaml loaded successfully]
[2023-10-26 01:24:59,924:INFO:common:yaml file: params.yaml loaded successfully]
[2023-10-26 01:24:59,925:INFO:common:yaml file: schema.yaml loaded successfully]
[2023-10-26 01:24:59,925:INFO:common:created directory at: artifacts]
[2023-10-26 01:24:59,925:INFO:common:created directory at: artifacts/model_evaluation]
[2023-10-26 01:25:04,973:INFO:common:json file saved at: artifacts\model_evaluation\metrics.json]
[2023-10-26 01:25:31,588:INFO:main:>>>>>> stage Model evaluation stage completed <<<<<<

x==========x]
[2023-10-26 01:26:54,850:INFO:utils:Note: NumExpr detected 16 cores but "NUMEXPR_MAX_THREADS" not set, so enforcing safe limit of 8.]
[2023-10-26 01:26:54,851:INFO:utils:NumExpr defaulting to 8 threads.]
[2023-10-26 01:26:56,510:INFO:main:>>>>>> stage Data Ingestion stage started <<<<<<]
[2023-10-26 01:26:56,513:INFO:common:yaml file: config\config.yaml loaded successfully]
[2023-10-26 01:26:56,519:INFO:common:yaml file: params.yaml loaded successfully]
[2023-10-26 01:26:56,520:INFO:common:yaml file: schema.yaml loaded successfully]
[2023-10-26 01:26:56,521:INFO:common:created directory at: artifacts]
[2023-10-26 01:26:56,522:INFO:common:created directory at: artifacts/data_ingestion]
[2023-10-26 01:26:56,522:INFO:data_ingestion:File already exists of size: ~ 94 KB]
[2023-10-26 01:26:56,525:INFO:main:>>>>>> stage Data Ingestion stage completed <<<<<<

x==========x]
[2023-10-26 01:26:56,525:INFO:main:>>>>>> stage Data Validation stage started <<<<<<]
[2023-10-26 01:26:56,528:INFO:common:yaml file: config\config.yaml loaded successfully]
[2023-10-26 01:26:56,528:INFO:common:yaml file: params.yaml loaded successfully]
[2023-10-26 01:26:56,530:INFO:common:yaml file: schema.yaml loaded successfully]
[2023-10-26 01:26:56,530:INFO:common:created directory at: artifacts]
[2023-10-26 01:26:56,530:INFO:common:created directory at: artifacts/data_validation]
[2023-10-26 01:26:56,538:INFO:main:>>>>>> stage Data Validation stage completed <<<<<<

x==========x]
[2023-10-26 01:26:56,538:INFO:main:>>>>>> stage Data Transformation stage started <<<<<<]
[2023-10-26 01:26:56,541:INFO:common:yaml file: config\config.yaml loaded successfully]
[2023-10-26 01:26:56,542:INFO:common:yaml file: params.yaml loaded successfully]
[2023-10-26 01:26:56,544:INFO:common:yaml file: schema.yaml loaded successfully]
[2023-10-26 01:26:56,544:INFO:common:created directory at: artifacts]
[2023-10-26 01:26:56,544:INFO:common:created directory at: artifacts/data_transformation]
[2023-10-26 01:26:56,559:INFO:data_transformation:Splited data into training and test sets]
[2023-10-26 01:26:56,559:INFO:data_transformation:(1199, 12)]
[2023-10-26 01:26:56,559:INFO:data_transformation:(400, 12)]
[2023-10-26 01:26:56,560:INFO:main:>>>>>> stage Data Transformation stage completed <<<<<<

x==========x]
[2023-10-26 01:26:56,560:INFO:main:>>>>>> stage Model Trainer stage started <<<<<<]
[2023-10-26 01:26:56,562:INFO:common:yaml file: config\config.yaml loaded successfully]
[2023-10-26 01:26:56,562:INFO:common:yaml file: params.yaml loaded successfully]
[2023-10-26 01:26:56,564:INFO:common:yaml file: schema.yaml loaded successfully]
[2023-10-26 01:26:56,565:INFO:common:created directory at: artifacts]
[2023-10-26 01:26:56,565:INFO:common:created directory at: artifacts/model_trainer]
[2023-10-26 01:26:56,587:INFO:main:>>>>>> stage Model Trainer stage completed <<<<<<

x==========x]
[2023-10-26 01:26:56,587:INFO:main:>>>>>> stage Model evaluation stage started <<<<<<]
[2023-10-26 01:26:56,589:INFO:common:yaml file: config\config.yaml loaded successfully]
[2023-10-26 01:26:56,591:INFO:common:yaml file: params.yaml loaded successfully]
[2023-10-26 01:26:56,592:INFO:common:yaml file: schema.yaml loaded successfully]
[2023-10-26 01:26:56,592:INFO:common:created directory at: artifacts]
[2023-10-26 01:26:56,592:INFO:common:created directory at: artifacts/model_evaluation]
[2023-10-26 01:26:57,812:INFO:common:json file saved at: artifacts\model_evaluation\metrics.json]
[2023-10-26 01:27:17,768:INFO:main:>>>>>> stage Model evaluation stage completed <<<<<<

x==========x]
